Workbook

Sheet 总览
A1: 7天海外版上线推进看板
A3: 原7天运营计划保留；新增“研发总览、开发进度、测试进度、模拟对局、部署方案”。开发/测试/部署请以新增工作表为主。
A5: 项目开始日期（可修改） | C5: 46215 | E5: 目标上线日期 | G5: =C5+6 -> 46221 | I5: 当前第几天 | K5: =MAX(1,MIN(7,TODAY()-C5+1)) -> 5 | M5: 使用方式：在“7天任务”中更新状态
A7: =COUNTA('7天任务'!E5:E200) -> 72 | C7: =COUNTIF('7天任务'!H5:H200,"已完成") -> 18 | E7: =COUNTIF('7天任务'!H5:H200,"进行中")+COUNTIF('7天任务'!H5:H200,"待审核") -> 5 | G7: =COUNTIF('7天任务'!H5:H200,"已阻塞") -> 0 | I7: =IFERROR(AVERAGE('7天任务'!I5:I200),0) -> 0.28472222
A10: 总任务 | C10: 已完成 | E10: 进行中 / 待审核 | G10: 已阻塞 | I10: 总体完成率
A12: 按分类查看进度 | H12: 按天查看进度
A13: 分类 | B13: 任务数 | C13: 已完成 | D13: 进行中/待审核 | E13: 已阻塞 | F13: 完成率 | H13: 天数 | I13: 日期 | J13: 任务数 | K13: 已完成 | L13: 已阻塞 | M13: 完成率
A14: 产品开发与上线 | B14: =COUNTIF('7天任务'!$D$5:$D$200,A14) -> 17 | C14: =COUNTIFS('7天任务'!$D$5:$D$200,A14,'7天任务'!$H$5:$H$200,"已完成") -> 2 | D14: =COUNTIFS('7天任务'!$D$5:$D$200,A14,'7天任务'!$H$5:$H$200,"进行中")+COUNTIFS('7天任务'!$D$5:$D$200,A14,'7天任务'!$H$5:$H$200,"待审核") -> 2 | E14: =COUNTIFS('7天任务'!$D$5:$D$200,A14,'7天任务'!$H$5:$H$200,"已阻塞") -> 0 | F14: =IFERROR(SUMIF('7天任务'!$D$5:$D$200,A14,'7天任务'!$I$5:$I$200)/COUNTIF('7天任务'!$D$5:$D$200,A14),0) -> 0.17647059 | H14: 第1天 | I14: =$C$5+0 -> 46215 | J14: =COUNTIF('7天任务'!$B$5:$B$200,1) -> 18 | K14: =COUNTIFS('7天任务'!$B$5:$B$200,1,'7天任务'!$H$5:$H$200,"已完成") -> 12 | L14: =COUNTIFS('7天任务'!$B$5:$B$200,1,'7天任务'!$H$5:$H$200,"已阻塞") -> 0 | M14: =IFERROR(SUMIF('7天任务'!$B$5:$B$200,1,'7天任务'!$I$5:$I$200)/COUNTIF('7天任务'!$B$5:$B$200,1),0) -> 0.72222222
A15: 产品付费与审核 | B15: =COUNTIF('7天任务'!$D$5:$D$200,A15) -> 9 | C15: =COUNTIFS('7天任务'!$D$5:$D$200,A15,'7天任务'!$H$5:$H$200,"已完成") -> 4 | D15: =COUNTIFS('7天任务'!$D$5:$D$200,A15,'7天任务'!$H$5:$H$200,"进行中")+COUNTIFS('7天任务'!$D$5:$D$200,A15,'7天任务'!$H$5:$H$200,"待审核") -> 1 | E15: =COUNTIFS('7天任务'!$D$5:$D$200,A15,'7天任务'!$H$5:$H$200,"已阻塞") -> 0 | F15: =IFERROR(SUMIF('7天任务'!$D$5:$D$200,A15,'7天任务'!$I$5:$I$200)/COUNTIF('7天任务'!$D$5:$D$200,A15),0) -> 0.5 | H15: 第2天 | I15: =$C$5+1 -> 46216 | J15: =COUNTIF('7天任务'!$B$5:$B$200,2) -> 13 | K15: =COUNTIFS('7天任务'!$B$5:$B$200,2,'7天任务'!$H$5:$H$200,"已完成") -> 6 | L15: =COUNTIFS('7天任务'!$B$5:$B$200,2,'7天任务'!$H$5:$H$200,"已阻塞") -> 0 | M15: =IFERROR(SUMIF('7天任务'!$B$5:$B$200,2,'7天任务'!$I$5:$I$200)/COUNTIF('7天任务'!$B$5:$B$200,2),0) -> 0.5
A16: 产品推广与内容 | B16: =COUNTIF('7天任务'!$D$5:$D$200,A16) -> 21 | C16: =COUNTIFS('7天任务'!$D$5:$D$200,A16,'7天任务'!$H$5:$H$200,"已完成") -> 4 | D16: =COUNTIFS('7天任务'!$D$5:$D$200,A16,'7天任务'!$H$5:$H$200,"进行中")+COUNTIFS('7天任务'!$D$5:$D$200,A16,'7天任务'!$H$5:$H$200,"待审核") -> 0 | E16: =COUNTIFS('7天任务'!$D$5:$D$200,A16,'7天任务'!$H$5:$H$200,"已阻塞") -> 0 | F16: =IFERROR(SUMIF('7天任务'!$D$5:$D$200,A16,'7天任务'!$I$5:$I$200)/COUNTIF('7天任务'!$D$5:$D$200,A16),0) -> 0.19047619 | H16: 第3天 | I16: =$C$5+2 -> 46217 | J16: =COUNTIF('7天任务'!$B$5:$B$200,3) -> 10 | K16: =COUNTIFS('7天任务'!$B$5:$B$200,3,'7天任务'!$H$5:$H$200,"已完成") -> 0 | L16: =COUNTIFS('7天任务'!$B$5:$B$200,3,'7天任务'!$H$5:$H$200,"已阻塞") -> 0 | M16: =IFERROR(SUMIF('7天任务'!$B$5:$B$200,3,'7天任务'!$I$5:$I$200)/COUNTIF('7天任务'!$B$5:$B$200,3),0) -> 0.05
A17: 用户测试与运营 | B17: =COUNTIF('7天任务'!$D$5:$D$200,A17) -> 8 | C17: =COUNTIFS('7天任务'!$D$5:$D$200,A17,'7天任务'!$H$5:$H$200,"已完成") -> 0 | D17: =COUNTIFS('7天任务'!$D$5:$D$200,A17,'7天任务'!$H$5:$H$200,"进行中")+COUNTIFS('7天任务'!$D$5:$D$200,A17,'7天任务'!$H$5:$H$200,"待审核") -> 0 | E17: =COUNTIFS('7天任务'!$D$5:$D$200,A17,'7天任务'!$H$5:$H$200,"已阻塞") -> 0 | F17: =IFERROR(SUMIF('7天任务'!$D$5:$D$200,A17,'7天任务'!$I$5:$I$200)/COUNTIF('7天任务'!$D$5:$D$200,A17),0) -> 0 | H17: 第4天 | I17: =$C$5+3 -> 46218 | J17: =COUNTIF('7天任务'!$B$5:$B$200,4) -> 9 | K17: =COUNTIFS('7天任务'!$B$5:$B$200,4,'7天任务'!$H$5:$H$200,"已完成") -> 0 | L17: =COUNTIFS('7天任务'!$B$5:$B$200,4,'7天任务'!$H$5:$H$200,"已阻塞") -> 0 | M17: =IFERROR(SUMIF('7天任务'!$B$5:$B$200,4,'7天任务'!$I$5:$I$200)/COUNTIF('7天任务'!$B$5:$B$200,4),0) -> 0.055555556
A18: 品牌与账号基础 | B18: =COUNTIF('7天任务'!$D$5:$D$200,A18) -> 6 | C18: =COUNTIFS('7天任务'!$D$5:$D$200,A18,'7天任务'!$H$5:$H$200,"已完成") -> 5 | D18: =COUNTIFS('7天任务'!$D$5:$D$200,A18,'7天任务'!$H$5:$H$200,"进行中")+COUNTIFS('7天任务'!$D$5:$D$200,A18,'7天任务'!$H$5:$H$200,"待审核") -> 1 | E18: =COUNTIFS('7天任务'!$D$5:$D$200,A18,'7天任务'!$H$5:$H$200,"已阻塞") -> 0 | F18: =IFERROR(SUMIF('7天任务'!$D$5:$D$200,A18,'7天任务'!$I$5:$I$200)/COUNTIF('7天任务'!$D$5:$D$200,A18),0) -> 0.91666667 | H18: 第5天 | I18: =$C$5+4 -> 46219 | J18: =COUNTIF('7天任务'!$B$5:$B$200,5) -> 8 | K18: =COUNTIFS('7天任务'!$B$5:$B$200,5,'7天任务'!$H$5:$H$200,"已完成") -> 0 | L18: =COUNTIFS('7天任务'!$B$5:$B$200,5,'7天任务'!$H$5:$H$200,"已阻塞") -> 0 | M18: =IFERROR(SUMIF('7天任务'!$B$5:$B$200,5,'7天任务'!$I$5:$I$200)/COUNTIF('7天任务'!$B$5:$B$200,5),0) -> 0
A19: 合规与风险 | B19: =COUNTIF('7天任务'!$D$5:$D$200,A19) -> 4 | C19: =COUNTIFS('7天任务'!$D$5:$D$200,A19,'7天任务'!$H$5:$H$200,"已完成") -> 3 | D19: =COUNTIFS('7天任务'!$D$5:$D$200,A19,'7天任务'!$H$5:$H$200,"进行中")+COUNTIFS('7天任务'!$D$5:$D$200,A19,'7天任务'!$H$5:$H$200,"待审核") -> 0 | E19: =COUNTIFS('7天任务'!$D$5:$D$200,A19,'7天任务'!$H$5:$H$200,"已阻塞") -> 0 | F19: =IFERROR(SUMIF('7天任务'!$D$5:$D$200,A19,'7天任务'!$I$5:$I$200)/COUNTIF('7天任务'!$D$5:$D$200,A19),0) -> 0.75 | H19: 第6天 | I19: =$C$5+5 -> 46220 | J19: =COUNTIF('7天任务'!$B$5:$B$200,6) -> 7 | K19: =COUNTIFS('7天任务'!$B$5:$B$200,6,'7天任务'!$H$5:$H$200,"已完成") -> 0 | L19: =COUNTIFS('7天任务'!$B$5:$B$200,6,'7天任务'!$H$5:$H$200,"已阻塞") -> 0 | M19: =IFERROR(SUMIF('7天任务'!$B$5:$B$200,6,'7天任务'!$I$5:$I$200)/COUNTIF('7天任务'!$B$5:$B$200,6),0) -> 0
A20: 测试与质量 | B20: =COUNTIF('7天任务'!$D$5:$D$200,A20) -> 3 | C20: =COUNTIFS('7天任务'!$D$5:$D$200,A20,'7天任务'!$H$5:$H$200,"已完成") -> 0 | D20: =COUNTIFS('7天任务'!$D$5:$D$200,A20,'7天任务'!$H$5:$H$200,"进行中")+COUNTIFS('7天任务'!$D$5:$D$200,A20,'7天任务'!$H$5:$H$200,"待审核") -> 0 | E20: =COUNTIFS('7天任务'!$D$5:$D$200,A20,'7天任务'!$H$5:$H$200,"已阻塞") -> 0 | F20: =IFERROR(SUMIF('7天任务'!$D$5:$D$200,A20,'7天任务'!$I$5:$I$200)/COUNTIF('7天任务'!$D$5:$D$200,A20),0) -> 0 | H20: 第7天 | I20: =$C$5+6 -> 46221 | J20: =COUNTIF('7天任务'!$B$5:$B$200,7) -> 7 | K20: =COUNTIFS('7天任务'!$B$5:$B$200,7,'7天任务'!$H$5:$H$200,"已完成") -> 0 | L20: =COUNTIFS('7天任务'!$B$5:$B$200,7,'7天任务'!$H$5:$H$200,"已阻塞") -> 0 | M20: =IFERROR(SUMIF('7天任务'!$B$5:$B$200,7,'7天任务'!$I$5:$I$200)/COUNTIF('7天任务'!$B$5:$B$200,7),0) -> 0
A21: 部署与运维 | B21: =COUNTIF('7天任务'!$D$5:$D$200,A21) -> 4 | C21: =COUNTIFS('7天任务'!$D$5:$D$200,A21,'7天任务'!$H$5:$H$200,"已完成") -> 0 | D21: =COUNTIFS('7天任务'!$D$5:$D$200,A21,'7天任务'!$H$5:$H$200,"进行中")+COUNTIFS('7天任务'!$D$5:$D$200,A21,'7天任务'!$H$5:$H$200,"待审核") -> 1 | E21: =COUNTIFS('7天任务'!$D$5:$D$200,A21,'7天任务'!$H$5:$H$200,"已阻塞") -> 0 | F21: =IFERROR(SUMIF('7天任务'!$D$5:$D$200,A21,'7天任务'!$I$5:$I$200)/COUNTIF('7天任务'!$D$5:$D$200,A21),0) -> 0.125
A23: 建议：原“7天任务”用于外部上线节奏；研发功能、自动测试、模拟对局和部署必须分别在新增工作表达到P0发布闸门。

Sheet 7天任务
A1: 7天海外版上线任务清单
A3: 只需重点维护：状态、实际完成日、卡点/问题、下一步动作、链接/备注。日期会根据总览中的开始日期自动计算。
A4: 编号 | B4: 天数 | C4: 日期 | D4: 分类 | E4: 任务 | F4: 交付/完成标准 | G4: 优先级 | H4: 状态 | I4: 自动进度 | J4: 外部依赖/等待对象 | K4: 负责人 | L4: 截止日 | M4: 实际完成日 | N4: 卡点/问题 | O4: 下一步动作 | P4: 链接/备注
A5: 1 | B5: 1 | C5: =总览!$C$5+B5-1 -> 46215 | D5: 品牌与账号基础 | E5: 确认英文产品名与统一品牌写法 | F5: 确定一个用于官网、社媒、Creem与itch.io的统一英文品牌名 | G5: P0 | H5: 已完成 | I5: =IF(H5="已完成",1,IF(H5="待审核",0.9,IF(H5="进行中",0.5,IF(H5="已阻塞",0.25,0)))) -> 1 | J5: 域名/商标检索 | K5: 我 | L5: =C5 -> 46215 | M5: 46215
A6: 2 | B6: 1 | C6: =总览!$C$5+B6-1 -> 46215 | D6: 品牌与账号基础 | E6: 注册产品域名 | F6: 域名已购买，可正常解析，续费信息已保存 | G6: P0 | H6: 已完成 | I6: =IF(H6="已完成",1,IF(H6="待审核",0.9,IF(H6="进行中",0.5,IF(H6="已阻塞",0.25,0)))) -> 1 | J6: 域名注册商 | K6: 我 | L6: =C6 -> 46215 | M6: 46215
A7: 3 | B7: 1 | C7: =总览!$C$5+B7-1 -> 46215 | D7: 品牌与账号基础 | E7: 配置HTTPS与基础DNS | F7: 官网域名可通过HTTPS访问，不出现证书错误 | G7: P0 | H7: 已完成 | I7: =IF(H7="已完成",1,IF(H7="待审核",0.9,IF(H7="进行中",0.5,IF(H7="已阻塞",0.25,0)))) -> 1 | J7: 域名注册商/托管平台 | K7: 我 | L7: =C7 -> 46215
A8: 4 | B8: 1 | C8: =总览!$C$5+B8-1 -> 46215 | D8: 品牌与账号基础 | E8: 配置客服邮箱 | F8: support@域名 邮箱可正常收发邮件 | G8: P0 | H8: 已完成 | I8: =IF(H8="已完成",1,IF(H8="待审核",0.9,IF(H8="进行中",0.5,IF(H8="已阻塞",0.25,0)))) -> 1 | J8: 邮箱服务商 | K8: 我 | L8: =C8 -> 46215
A9: 5 | B9: 1 | C9: =总览!$C$5+B9-1 -> 46215 | D9: 产品付费与审核 | E9: 注册Creem并创建商店 | F9: Creem后台可访问，商店名称与品牌一致 | G9: P0 | H9: 已完成 | I9: =IF(H9="已完成",1,IF(H9="待审核",0.9,IF(H9="进行中",0.5,IF(H9="已阻塞",0.25,0)))) -> 1 | J9: Creem | K9: 我 | L9: =C9 -> 46215
A10: 6 | B10: 1 | C10: =总览!$C$5+B10-1 -> 46215 | D10: 产品付费与审核 | E10: 确认个人入驻资料 | F10: 实名认证姓名、国家、税务居民信息与收款账户一致 | G10: P0 | H10: 已完成 | I10: =IF(H10="已完成",1,IF(H10="待审核",0.9,IF(H10="进行中",0.5,IF(H10="已阻塞",0.25,0)))) -> 1 | J10: 个人证件/支付宝 | K10: 我 | L10: =C10 -> 46215
A11: 7 | B11: 1 | C11: =总览!$C$5+B11-1 -> 46215 | D11: 产品付费与审核 | E11: 提交KYC/KYB认证 | F11: 认证已提交，后台显示审核中或已通过 | G11: P0 | H11: 已完成 | I11: =IF(H11="已完成",1,IF(H11="待审核",0.9,IF(H11="进行中",0.5,IF(H11="已阻塞",0.25,0)))) -> 1 | J11: Creem审核 | K11: 我 | L11: =C11 -> 46215
A12: 8 | B12: 1 | C12: =总览!$C$5+B12-1 -> 46215 | D12: 产品推广与内容 | E12: 注册TikTok账号 | F12: 账号注册成功，用户名已占用并记录 | G12: P1 | H12: 已完成 | I12: =IF(H12="已完成",1,IF(H12="待审核",0.9,IF(H12="进行中",0.5,IF(H12="已阻塞",0.25,0)))) -> 1 | J12: TikTok | K12: 我 | L12: =C12 -> 46215
A13: 9 | B13: 1 | C13: =总览!$C$5+B13-1 -> 46215 | D13: 产品推广与内容 | E13: 注册YouTube频道 | F13: 频道创建成功，Handle已占用并记录 | G13: P1 | H13: 已完成 | I13: =IF(H13="已完成",1,IF(H13="待审核",0.9,IF(H13="进行中",0.5,IF(H13="已阻塞",0.25,0)))) -> 1 | J13: YouTube | K13: 我 | L13: =C13 -> 46215
A14: 10 | B14: 1 | C14: =总览!$C$5+B14-1 -> 46215 | D14: 产品推广与内容 | E14: 注册X账号 | F14: 账号注册成功，用户名已占用并记录 | G14: P2 | H14: 未开始 | I14: =IF(H14="已完成",1,IF(H14="待审核",0.9,IF(H14="进行中",0.5,IF(H14="已阻塞",0.25,0)))) -> 0 | J14: X | K14: 我 | L14: =C14 -> 46215
A15: 11 | B15: 1 | C15: =总览!$C$5+B15-1 -> 46215 | D15: 产品推广与内容 | E15: 注册Reddit账号 | F15: 账号注册成功，完成基础安全设置 | G15: P1 | H15: 未开始 | I15: =IF(H15="已完成",1,IF(H15="待审核",0.9,IF(H15="进行中",0.5,IF(H15="已阻塞",0.25,0)))) -> 0 | J15: Reddit | K15: 我 | L15: =C15 -> 46215
A16: 12 | B16: 1 | C16: =总览!$C$5+B16-1 -> 46215 | D16: 产品推广与内容 | E16: 创建Discord服务器 | F16: 服务器创建成功，邀请链接可用 | G16: P1 | H16: 已完成 | I16: =IF(H16="已完成",1,IF(H16="待审核",0.9,IF(H16="进行中",0.5,IF(H16="已阻塞",0.25,0)))) -> 1 | J16: Discord | K16: 我 | L16: =C16 -> 46215
A17: 13 | B17: 1 | C17: =总览!$C$5+B17-1 -> 46215 | D17: 产品推广与内容 | E17: 注册itch.io账号 | F17: 账号可登录，已具备创建项目页权限 | G17: P1 | H17: 已完成 | I17: =IF(H17="已完成",1,IF(H17="待审核",0.9,IF(H17="进行中",0.5,IF(H17="已阻塞",0.25,0)))) -> 1 | J17: itch.io | K17: 我 | L17: =C17 -> 46215
A18: 14 | B18: 1 | C18: =总览!$C$5+B18-1 -> 46215 | D18: 品牌与账号基础 | E18: 锁定统一用户名 | F18: 各渠道用户名尽量一致，并在账号表中记录 | G18: P1 | H18: 已完成 | I18: =IF(H18="已完成",1,IF(H18="待审核",0.9,IF(H18="进行中",0.5,IF(H18="已阻塞",0.25,0)))) -> 1 | J18: 各平台账号 | K18: 我 | L18: =C18 -> 46215
... A56: 52 | B56: 7 | C56: =总览!$C$5+B56-1 -> 46221 | D56: 用户测试与运营 | E56: 完成上线复盘与下周决策 | F56: 汇总流量、试玩、付费意愿、审核状态和下周优先级 | G56: P0 | H56: 未开始 | I56: =IF(H56="已完成",1,IF(H56="待审核",0.9,IF(H56="进行中",0.5,IF(H56="已阻塞",0.25,0)))) -> 0 | J56: 数据与反馈 | K56: 我 | L56: =C56 -> 46221
A57: 53 | B57: 1 | C57: =总览!$C$5+B57-1 -> 46215 | D57: 产品开发与上线 | E57: 完成现有代码与需求差距审计 | F57: 按唯一工程基线形成已实现/缺失/冲突清单；明确登录、房间、API、AI、数据库与部署缺口 | G57: P0 | H57: 进行中 | I57: =IF(H57="已完成",1,IF(H57="待审核",0.9,IF(H57="进行中",0.5,IF(H57="已阻塞",0.25,0)))) -> 0.5 | J57: 需求文档/代码仓库 | K57: 我/Codex | L57: =C57 -> 46215 | N57: 当前功能约30%，缺口较多 | O57: 先完成代码审计 | P57: 详见“开发进度”
A58: 54 | B58: 1 | C58: =总览!$C$5+B58-1 -> 46215 | D58: 产品开发与上线 | E58: 建立Supabase开发环境 | F58: Supabase Auth/Postgres可连接；密钥分前端anon与服务端service role | G58: P0 | H58: 未开始 | I58: =IF(H58="已完成",1,IF(H58="待审核",0.9,IF(H58="进行中",0.5,IF(H58="已阻塞",0.25,0)))) -> 0 | J58: Supabase | K58: 我/Codex | L58: =C58 -> 46215 | O58: 创建项目并保存环境变量 | P58: 详见“部署方案”
A59: 55 | B59: 1 | C59: =总览!$C$5+B59-1 -> 46215 | D59: 部署与运维 | E59: 确定MVP部署架构 | F59: 明确Vercel前端、NestJS后端、Supabase数据库/Auth、LLM和Creem的部署方式 | G59: P0 | H59: 进行中 | I59: =IF(H59="已完成",1,IF(H59="待审核",0.9,IF(H59="进行中",0.5,IF(H59="已阻塞",0.25,0)))) -> 0.5 | J59: Vercel/Railway/Supabase | K59: 我 | L59: =C59 -> 46215 | O59: 确认后端是否部署Railway | P59: 详见“部署方案”
A60: 56 | B60: 2 | C60: =总览!$C$5+B60-1 -> 46216 | D60: 产品开发与上线 | E60: 实现登录/注册与会话恢复 | F60: 邮箱登录可用；刷新、退出、重新登录和受保护路由正常 | G60: P0 | H60: 未开始 | I60: =IF(H60="已完成",1,IF(H60="待审核",0.9,IF(H60="进行中",0.5,IF(H60="已阻塞",0.25,0)))) -> 0 | J60: Supabase Auth | K60: Codex | L60: =C60 -> 46216 | N60: 当前缺少登录 | O60: 实现Magic Link/OTP与路由保护 | P60: 详见“开发进度”
A61: 57 | B61: 2 | C61: =总览!$C$5+B61-1 -> 46216 | D61: 产品开发与上线 | E61: 实现创建故事局/开启房间 | F61: 登录后可创建StoryRun并跳转 /game?runId；双击不重复创建 | G61: P0 | H61: 未开始 | I61: =IF(H61="已完成",1,IF(H61="待审核",0.9,IF(H61="进行中",0.5,IF(H61="已阻塞",0.25,0)))) -> 0 | J61: 登录/StoryRun API | K61: Codex | L61: =C61 -> 46216 | N61: 当前缺少开启房间 | O61: 实现POST /api/v4/story-runs | P61: 详见“开发进度”
A62: 58 | B62: 2 | C62: =总览!$C$5+B62-1 -> 46216 | D62: 产品开发与上线 | E62: 实现进入与恢复房间 | F62: 输入runId或“继续游戏”可恢复；无效和越权runId明确拒绝 | G62: P0 | H62: 未开始 | I62: =IF(H62="已完成",1,IF(H62="待审核",0.9,IF(H62="进行中",0.5,IF(H62="已阻塞",0.25,0)))) -> 0 | J62: 登录/GET run | K62: Codex | L62: =C62 -> 46216 | N62: 当前缺少进入房间 | O62: 实现我的游戏与恢复入口 | P62: 详见“开发进度”
A63: 59 | B63: 2 | C63: =总览!$C$5+B63-1 -> 46216 | D63: 产品开发与上线 | E63: 数据库化StoryRun/StoryEvent/AiTask | F63: 运行态进入Supabase PostgreSQL；浏览器只保存runId和非权威UI状态 | G63: P0 | H63: 未开始 | I63: =IF(H63="已完成",1,IF(H63="待审核",0.9,IF(H63="进行中",0.5,IF(H63="已阻塞",0.25,0)))) -> 0 | J63: Supabase/Prisma | K63: Codex | L63: =C63 -> 46216 | O63: 执行Schema与迁移 | P63: 详见“开发进度”
A64: 60 | B64: 3 | C64: =总览!$C$5+B64-1 -> 46217 | D64: 产品开发与上线 | E64: 完成v4核心API闭环 | F64: stories/roles/create/get/messages/dashboard/decision/maneuver/advance/finalize可用 | G64: P0 | H64: 未开始 | I64: =IF(H64="已完成",1,IF(H64="待审核",0.9,IF(H64="进行中",0.5,IF(H64="已阻塞",0.25,0)))) -> 0 | J64: NestJS/数据库 | K64: Codex | L64: =C64 -> 46217 | O64: 按API契约逐个实现 | P64: 详见“开发进度”
A65: 61 | B65: 3 | C65: =总览!$C$5+B65-1 -> 46217 | D65: 产品开发与上线 | E65: 完成主游戏8种UI状态接入 | F65: 单路由、固定三栏、持续叙事、决策、推演、变化、记录、弹窗和谋划全部接真实状态 | G65: P0 | H65: 进行中 | I65: =IF(H65="已完成",1,IF(H65="待审核",0.9,IF(H65="进行中",0.5,IF(H65="已阻塞",0.25,0)))) -> 0.5 | J65: v4 API/现有UI | K65: Codex | L65: =C65 -> 46217 | N65: UI已有设计但功能未闭环 | O65: 按状态机接入真实数据 | P65: 详见“开发进度”
A66: 62 | B66: 3 | C66: =总览!$C$5+B66-1 -> 46217 | D66: 产品开发与上线 | E66: 实现主线决策与ActionGuard | F66: A/B/C回填、1-200字、越权拦截、规则补丁、幂等与version冲突正常 | G66: P0 | H66: 未开始 | I66: =IF(H66="已完成",1,IF(H66="待审核",0.9,IF(H66="进行中",0.5,IF(H66="已阻塞",0.25,0)))) -> 0 | J66: 规则引擎/API | K66: Codex | L66: =C66 -> 46217 | O66: 先完成预设选项，再接自定义Guard | P66: 详见“开发进度”
A67: 63 | B67: 3 | C67: =总览!$C$5+B67-1 -> 46217 | D67: 产品开发与上线 | E67: 实现主动谋划与关键事件 | F67: 每日2次谋划；接触/调查/筹码/自拟；关键事件立即或稍后处理 | G67: P0 | H67: 未开始 | I67: =IF(H67="已完成",1,IF(H67="待审核",0.9,IF(H67="进行中",0.5,IF(H67="已阻塞",0.25,0)))) -> 0 | J67: 规则引擎/API | K67: Codex | L67: =C67 -> 46217 | O67: 实现计数、跨日重置和defer | P67: 详见“开发进度”
A68: 64 | B68: 4 | C68: =总览!$C$5+B68-1 -> 46218 | D68: 产品开发与上线 | E68: 接入AI结构化输出与Fallback | F68: 真实模型输出Schema校验；超时重试1次；双失败规则Fallback完成落账 | G68: P0 | H68: 未开始 | I68: =IF(H68="已完成",1,IF(H68="待审核",0.9,IF(H68="进行中",0.5,IF(H68="已阻塞",0.25,0)))) -> 0 | J68: LLM/AiTask | K68: Codex | L68: =C68 -> 46218 | O68: 先mock后真实模型 | P68: 详见“开发进度”
A69: 65 | B69: 4 | C69: =总览!$C$5+B69-1 -> 46218 | D69: 产品付费与审核 | E69: 跑通Creem Test支付闭环 | F69: 创建Checkout、Webhook签名、重复通知幂等、支付后权益可见 | G69: P0 | H69: 进行中 | I69: =IF(H69="已完成",1,IF(H69="待审核",0.9,IF(H69="进行中",0.5,IF(H69="已阻塞",0.25,0)))) -> 0.5 | J69: Creem/公网API | K69: 我/Codex | L69: =C69 -> 46218 | N69: Webhook与密钥仍需完整验证 | O69: 完成Test Mode端到端支付 | P69: 详见“开发进度/部署方案”
A70: 66 | B70: 4 | C70: =总览!$C$5+B70-1 -> 46218 | D70: 产品开发与上线 | E70: 实现日志、埋点与安全隔离 | F70: 结构化日志、核心漏斗埋点、RLS/CORS、HTML转义和私密字段扫描生效 | G70: P0 | H70: 未开始 | I70: =IF(H70="已完成",1,IF(H70="待审核",0.9,IF(H70="进行中",0.5,IF(H70="已阻塞",0.25,0)))) -> 0 | J70: API/前端/Supabase | K70: Codex | L70: =C70 -> 46218 | O70: 先做P0安全和错误日志 | P70: 详见“开发进度”
A71: 67 | B71: 5 | C71: =总览!$C$5+B71-1 -> 46219 | D71: 测试与质量 | E71: 完成P0自动化测试 | F71: 功能、Guard、因果、信息隔离、并发、恢复与UI的P0用例全部通过 | G71: P0 | H71: 未开始 | I71: =IF(H71="已完成",1,IF(H71="待审核",0.9,IF(H71="进行中",0.5,IF(H71="已阻塞",0.25,0)))) -> 0 | J71: 测试脚本/CI | K71: Codex | L71: =C71 -> 46219 | N71: 当前缺少系统测试 | O71: 按“测试进度”逐项执行 | P71: 详见“测试进度”
A72: 68 | B72: 5 | C72: =总览!$C$5+B72-1 -> 46219 | D72: 测试与质量 | E72: 完成至少20局模拟测试 | F72: 覆盖A/B/C/Mixed、0/1/2谋划、关键事件、AI故障、刷新和并发 | G72: P0 | H72: 未开始 | I72: =IF(H72="已完成",1,IF(H72="待审核",0.9,IF(H72="进行中",0.5,IF(H72="已阻塞",0.25,0)))) -> 0 | J72: staging/mock/真实模型 | K72: Codex/我 | L72: =C72 -> 46219 | N72: 当前缺少模拟测试 | O72: 先自动模拟，再人工试玩 | P72: 详见“模拟对局”
A73: 69 | B73: 5 | C73: =总览!$C$5+B73-1 -> 46219 | D73: 测试与质量 | E73: 完成安全与信息隔离检查 | F73: 用户越权、前台私密字段、HTML注入、密钥泄露和日志脱敏全部通过 | G73: P0 | H73: 未开始 | I73: =IF(H73="已完成",1,IF(H73="待审核",0.9,IF(H73="进行中",0.5,IF(H73="已阻塞",0.25,0)))) -> 0 | J73: 安全扫描/HTTP | K73: Codex | L73: =C73 -> 46219 | O73: 执行I类、AUTH和DEP安全用例 | P73: 详见“测试进度”
A74: 70 | B74: 6 | C74: =总览!$C$5+B74-1 -> 46220 | D74: 部署与运维 | E74: 部署staging环境 | F74: Vercel Web、API、Supabase、Creem Test、真实AI与Fallback独立可用 | G74: P0 | H74: 未开始 | I74: =IF(H74="已完成",1,IF(H74="待审核",0.9,IF(H74="进行中",0.5,IF(H74="已阻塞",0.25,0)))) -> 0 | J74: Vercel/Railway/Supabase | K74: 我/Codex | L74: =C74 -> 46220 | O74: 按部署任务表配置 | P74: 详见“部署方案”
A75: 71 | B75: 6 | C75: =总览!$C$5+B75-1 -> 46220 | D75: 部署与运维 | E75: 完成冒烟、备份、监控和回滚演练 | F75: staging端到端通过；备份可恢复；日志告警和上一版本回滚可用 | G75: P0 | H75: 未开始 | I75: =IF(H75="已完成",1,IF(H75="待审核",0.9,IF(H75="进行中",0.5,IF(H75="已阻塞",0.25,0)))) -> 0 | J75: staging/监控 | K75: 我/Codex | L75: =C75 -> 46220 | O75: 执行DEP用例 | P75: 详见“部署方案/测试进度”
A76: 72 | B76: 7 | C76: =总览!$C$5+B76-1 -> 46221 | D76: 部署与运维 | E76: 生产部署与最终发布闸门 | F76: P0开发完成、P0测试通过、20局无死路、生产冒烟通过后才公开Beta | G76: P0 | H76: 未开始 | I76: =IF(H76="已完成",1,IF(H76="待审核",0.9,IF(H76="进行中",0.5,IF(H76="已阻塞",0.25,0)))) -> 0 | J76: 全部前置 | K76: 我/Codex | L76: =C76 -> 46221 | O76: 完成发布评审并记录版本 | P76: 详见“研发总览/上线验收”

Sheet 账号与外部依赖
A1: 账号、审核与外部依赖追踪
A3: 将所有会卡住上线的外部事项集中记录：账号、审核、域名、邮箱、政策页、创作者和社区。
A4: 类型 | B4: 平台/事项 | C4: 用途 | D4: 目标用户名/名称 | E4: 注册状态 | F4: 资料完善 | G4: 审核状态 | H4: URL/入口 | I4: 下一步 | J4: 备注
A5: 基础设施 | B5: 产品域名 | C5: 官网与品牌入口 | E5: 已完成 | F5: 未开始 | G5: 不适用 | I5: 注册并解析
A6: 基础设施 | B6: 客服邮箱 | C6: Creem审核与用户支持 | D6: support@你的域名 | E6: 已完成 | F6: 未开始 | G6: 不适用 | I6: 配置收发与签名
A7: 支付审核 | B7: Creem | C7: 海外收款与税务处理 | E7: 已注册 | F7: 进行中 | G7: 待审核 | I7: 完成KYC/审核 | J7: 当前处于测试模式
A8: 推广账号 | B8: TikTok | C8: 短视频自然流量 | E8: 未开始 | F8: 未开始 | G8: 不适用 | I8: 注册并锁定用户名
A9: 推广账号 | B9: YouTube | C9: Shorts与长期内容 | E9: 未开始 | F9: 未开始 | G9: 不适用 | I9: 创建频道
A10: 推广账号 | B10: X | C10: 开发者传播与更新 | E10: 未开始 | F10: 未开始 | G10: 不适用 | I10: 注册并完善资料
A11: 推广账号 | B11: Reddit | C11: 高意愿测试用户 | E11: 未开始 | F11: 未开始 | G11: 不适用 | I11: 注册并观察社区规则
A12: 社区运营 | B12: Discord | C12: 测试组织与长期社群 | E12: 未开始 | F12: 未开始 | G12: 不适用 | I12: 创建服务器和频道
A13: 游戏平台 | B13: itch.io | C13: 浏览器游戏展示与可信度 | E13: 未开始 | F13: 未开始 | G13: 待审核 | I13: 创建项目草稿
A14: 合规页面 | B14: Privacy Policy | C14: 数据与隐私说明 | E14: 未开始 | F14: 未开始 | G14: 不适用 | I14: 发布并链接到页脚
A15: 合规页面 | B15: Terms of Service | C15: 用户规则与责任边界 | E15: 未开始 | F15: 未开始 | G15: 不适用 | I15: 发布并链接到页脚
A16: 合规页面 | B16: Refund Policy | C16: 退款条件和处理时限 | E16: 未开始 | F16: 未开始 | G16: 不适用 | I16: 发布并链接到页脚
A17: 推广资源 | B17: 小型内容创作者 | C17: 试玩与内容合作 | E17: 未开始 | F17: 未开始 | G17: 待联系 | I17: 建立名单并逐一联系
A18: 推广资源 | B18: 目标社区清单 | C18: Reddit/Discord/TTRPG/AI游戏 | E18: 未开始 | F18: 未开始 | G18: 待研究 | I18: 记录规则和发帖窗口

Sheet 上线验收
A1: 海外 Limited Beta 上线验收清单
A3: 只有“上线必须项”全部完成或有明确备用方案时，才执行第7天公开发布。
A4: 分类 | B4: 验收项 | C4: 完成标准 | D4: 是否必须 | E4: 状态 | F4: 证据/链接 | G4: 负责人 | H4: 备注
A5: 基础设施 | B5: 独立域名与HTTPS | C5: 官网通过HTTPS稳定访问 | D5: 必须 | E5: 已完成 | G5: 我
A6: 基础设施 | B6: 客服邮箱可用 | C6: support@域名 可正常收发 | D6: 必须 | E6: 已完成 | G6: 我
A7: 网站 | B7: 英文首页已上线 | C7: 价值主张、试玩入口、价格清晰 | D7: 必须 | E7: 未开始 | G7: 我
A8: 网站 | B8: 移动端可访问 | C8: 手机浏览不影响阅读和转化 | D8: 必须 | E8: 未开始 | G8: 我
A9: 合规 | B9: Privacy Policy | C9: 页面公开且页脚可访问 | D9: 必须 | E9: 已完成 | G9: 我
A10: 合规 | B10: Terms of Service | C10: 页面公开且页脚可访问 | D10: 必须 | E10: 已完成 | G10: 我
A11: 合规 | B11: Refund Policy | C11: 页面公开且价格页可访问 | D11: 必须 | E11: 已完成 | G11: 我
A12: 支付 | B12: Creem KYC已提交 | C12: 后台显示审核中或已通过 | D12: 必须 | E12: 未开始 | G12: 我
A13: 支付 | B13: Creem真实收款可用或有备用方案 | C13: Live支付可用；否则Founder候补可用 | D13: 必须 | E13: 未开始 | G13: 我
A14: 支付 | B14: 商品名称与价格一致 | C14: 官网、Creem与退款政策描述一致 | D14: 必须 | E14: 未开始 | G14: 我
A15: 推广 | B15: 至少5条短视频已准备 | C15: 可直接发布，含统一落地页链接 | D15: 必须 | E15: 未开始 | G15: 我
A16: 推广 | B16: 主要社媒账号可用 | C16: TikTok、YouTube至少已注册并完善 | D16: 必须 | E16: 未开始 | G16: 我
... A22: 备用方案 | B22: Creem未通过时不阻塞上线 | C22: 免费Beta+Founder候补入口已测试 | D22: 必须 | E22: 未开始 | G22: 我
A23: 账号 | B23: 用户登录与会话恢复 | C23: 邮箱登录可用；刷新与重新登录可恢复账号和历史故事局 | D23: 必须 | E23: 未开始 | G23: 我/Codex | H23: 缺少登录时不能形成付费账号闭环
A24: 核心功能 | B24: 创建故事局/开启房间 | C24: 登录后可创建StoryRun并进入/game?runId | D24: 必须 | E24: 未开始 | G24: Codex | H24: 幂等创建，不重复产生房间
A25: 核心功能 | B25: 进入与恢复房间 | C25: 有效runId可恢复；无效/越权runId明确拒绝 | D25: 必须 | E25: 未开始 | G25: Codex | H25: 浏览器不保存权威状态
A26: 核心功能 | B26: 7天主线闭环 | C26: 第1-6天共12次主线决策，第7天完成全局与个人结局 | D26: 必须 | E26: 未开始 | G26: Codex | H26: 至少一条完整路径通过
A27: 核心功能 | B27: 主动谋划与关键事件 | C27: 每天最多2次谋划；关键事件可立即/稍后并正确计数 | D27: 必须 | E27: 未开始 | G27: Codex | H27: 不替代主线决策
A28: AI稳定性 | B28: AI重试与规则Fallback | C28: AI连续失败时仍能正常落账和完成一局，用户不见技术错误 | D28: 必须 | E28: 未开始 | G28: Codex | H28: fallback失败才显示可恢复错误
A29: 数据安全 | B29: 登录权限与私密字段隔离 | C29: 用户不能读取他人局；公共响应无隐藏推理、内部收益风险和密钥 | D29: 必须 | E29: 未开始 | G29: Codex | H29: 安全扫描必须通过
A30: 测试 | B30: P0自动化测试通过 | C30: 功能、ActionGuard、并发、恢复、UI与信息隔离P0用例100%通过 | D30: 必须 | E30: 未开始 | G30: Codex | H30: 详见“测试进度”
A31: 测试 | B31: 20局连续模拟通过 | C31: A/B/C/Mixed、0/1/2谋划、故障恢复均无死路 | D31: 必须 | E31: 未开始 | G31: Codex | H31: 详见“模拟对局”
A32: 部署 | B32: Staging完整可用 | C32: 独立数据库、Creem Test、真实模型+fallback、日志与告警可用 | D32: 必须 | E32: 未开始 | G32: 我/Codex | H32: 不能与production共享密钥
A33: 部署 | B33: Production部署与备份 | C33: Web、API、Supabase、域名、迁移、备份、回滚和Health Check完成 | D33: 必须 | E33: 未开始 | G33: 我/Codex | H33: 详见“部署方案”
A34: 上线闸门 | B34: 生产冒烟与回滚演练 | C34: 首页→登录→创建局→决策→刷新恢复→支付/候补全链路通过 | D34: 必须 | E34: 未开始 | G34: 我/Codex | H34: 失败则停止公开发布

Sheet 开发进度
A1: AI多人剧情推演｜MVP开发进度
A3: 核验更新（2026-07-15）：已按当前代码、自动化测试与 Railway test 运行状态回填。已完成代表当前代码/测试证据成立；待审核代表实现已具备但 Vercel 正式发布、完整视觉验收或 Creem Dashboard 证据尚未闭环。
A4: 编号 | B4: 模块 | C4: 子模块 | D4: 功能/任务 | E4: 实现说明 | F4: 交付/验收标准 | G4: 需求依据 | H4: 优先级 | I4: 上线阻断 | J4: 状态 | K4: 自动进度 | L4: 前置依赖 | M4: 建议阶段 | N4: 负责人 | O4: 计划完成日 | P4: 实际完成日 | Q4: 卡点/问题 | R4: 下一步动作 | S4: 证据/链接
A5: DEV-001 | B5: 工程基线 | C5: 仓库审计 | D5: 核对现有代码与唯一工程基线 | E5: 盘点 apps/web、apps/api、packages/shared、packages/templates、Prisma 和现有分支，形成“已实现/缺失/冲突”清单。 | F5: 清单覆盖登录、入口、StoryRun、8种UI状态、AI、数据库、测试和部署；所有冲突有处理结论。 | G5: 01基线§1-2；07 PRD§18 | H5: P0 | I5: 是 | J5: 已完成 | K5: =IF(J5="不适用","",IF(J5="已完成",1,IF(J5="待审核",0.9,IF(J5="进行中",0.5,IF(J5="已阻塞",0.25,0))))) -> 1 | M5: 第1天 | N5: Codex+我 | O5: =总览!$C$5+0 -> 46215 | Q5: 2026-07-15：已按当前仓库、脚本与测试复核。 | R5: 随需求变化维护基线与契约。 | S5: pnpm test:api、pnpm --filter @apps/web typecheck、pnpm lint:config 均通过。
A6: DEV-002 | B6: 工程基线 | C6: 范围锁定 | D6: 锁定 Web 单人 MVP 范围 | E6: 当前只做《桑田诏》、浙江总督、7天、12次主线决策、每日2次谋划；真人多人仅预留。 | F6: 代码、页面和接口不存在同时开发真人多人/小程序/两套前端的分叉。 | G6: 01基线§2；07 PRD§3 | H6: P0 | I6: 是 | J6: 不适用 | K6: =IF(J6="不适用","",IF(J6="已完成",1,IF(J6="待审核",0.9,IF(J6="进行中",0.5,IF(J6="已阻塞",0.25,0))))) | L6: 代码审计 | M6: 第1天 | N6: 我 | O6: =总览!$C$5+0 -> 46215 | Q6: 原表限定单人MVP/禁止真人多人；现行代码已演进为房间与多用户实现，原验收口径不再适用。 | R6: 后续以 v1.4 房间/多用户范围重建对应任务与验收口径。 | S6: apps/api/src/rooms.controller.ts；docs/auto-execute/many-worlds-v14-p0-closeout-final-acceptance-gate.md
A7: DEV-003 | B7: 工程基线 | C7: 前端基线 | D7: 确认 apps/web 为唯一正式前端 | E7: 沿用现有 apps/web，不新建 player-web，不在本轮迁移技术栈。 | F7: 构建与部署只产出一套正式 Web；路由符合基线。 | G7: 01基线§5 | H7: P0 | I7: 是 | J7: 已完成 | K7: =IF(J7="不适用","",IF(J7="已完成",1,IF(J7="待审核",0.9,IF(J7="进行中",0.5,IF(J7="已阻塞",0.25,0))))) -> 1 | L7: 代码审计 | M7: 第1天 | N7: Codex | O7: =总览!$C$5+0 -> 46215 | Q7: 2026-07-15：已按当前仓库、脚本与测试复核。 | R7: 随需求变化维护基线与契约。 | S7: pnpm test:api、pnpm --filter @apps/web typecheck、pnpm lint:config 均通过。
A8: DEV-004 | B8: 工程基线 | C8: 后端基线 | D8: 确认 apps/api NestJS 与 /api/v4 | E8: 统一 API 前缀、异常格式、共享类型和请求校验。 | F8: 健康检查与 v4 路由可访问，旧接口仅在适配层保留。 | G8: 01基线§6；02状态机§9 | H8: P0 | I8: 是 | J8: 已完成 | K8: =IF(J8="不适用","",IF(J8="已完成",1,IF(J8="待审核",0.9,IF(J8="进行中",0.5,IF(J8="已阻塞",0.25,0))))) -> 1 | L8: 代码审计 | M8: 第1天 | N8: Codex | O8: =总览!$C$5+0 -> 46215 | Q8: 2026-07-15：已按当前仓库、脚本与测试复核。 | R8: 随需求变化维护基线与契约。 | S8: pnpm test:api、pnpm --filter @apps/web typecheck、pnpm lint:config 均通过。
A9: DEV-005 | B9: 工程基线 | C9: 共享契约 | D9: 统一字段与共享类型 | E9: 统一 templateKey、selectedRoleKey、runId、eventId、version、optionKey、customText、maneuverType 等字段。 | F9: 前后端编译通过；新接口无 storyId/templateId/messageId 混用。 | G9: 01基线§6.2；02状态机§1 | H9: P0 | I9: 是 | J9: 已完成 | K9: =IF(J9="不适用","",IF(J9="已完成",1,IF(J9="待审核",0.9,IF(J9="进行中",0.5,IF(J9="已阻塞",0.25,0))))) -> 1 | L9: 后端基线 | M9: 第1天 | N9: Codex | O9: =总览!$C$5+0 -> 46215 | Q9: 2026-07-15：已按当前仓库、脚本与测试复核。 | R9: 随需求变化维护基线与契约。 | S9: pnpm test:api、pnpm --filter @apps/web typecheck、pnpm lint:config 均通过。
A10: DEV-006 | B10: 工程基线 | C10: 配置校验 | D10: 接入剧本 JSON Schema 与跨文件 lint | E10: 将 Markdown 剧本编译为 story/roles/days/decisions/maneuvers/leverage/endings/context-cards JSON，并用 AJV 校验。 | F10: 构建时能发现缺失角色、无效变量、超过12个决策、不可达结局、公共字段泄露。 | G10: 03 Schema§1-12 | H10: P0 | I10: 是 | J10: 已完成 | K10: =IF(J10="不适用","",IF(J10="已完成",1,IF(J10="待审核",0.9,IF(J10="进行中",0.5,IF(J10="已阻塞",0.25,0))))) -> 1 | L10: 共享契约 | M10: 第2天 | N10: Codex | O10: =总览!$C$5+1 -> 46216 | Q10: 2026-07-15：已按当前仓库、脚本与测试复核。 | R10: 随需求变化维护基线与契约。 | S10: pnpm test:api、pnpm --filter @apps/web typecheck、pnpm lint:config 均通过。
A11: DEV-007 | B11: 工程基线 | C11: 构建命令 | D11: 统一本地与 CI 命令 | E11: 配置 install、typecheck、config lint、unit、service、HTTP、E2E 和安全投影测试命令。 | F11: README/脚本可一键执行；失败会阻止发布。 | G11: 04验收§11 | H11: P0 | I11: 是 | J11: 进行中 | K11: =IF(J11="不适用","",IF(J11="已完成",1,IF(J11="待审核",0.9,IF(J11="进行中",0.5,IF(J11="已阻塞",0.25,0))))) -> 0.5 | L11: 配置校验 | M11: 第5天 | N11: Codex | O11: =总览!$C$5+4 -> 46219 | Q11: 本地命令已具备并通过本轮核验；CI 发布闸门未取得当前远端证据。 | R11: 补充 CI 执行记录与失败阻断证明。 | S11: package.json scripts；本轮本地校验通过。
A12: DEV-008 | B12: 工程基线 | C12: 环境分层 | D12: 建立 local/test/staging/production 配置 | E12: 四套环境数据、密钥、AI预算隔离；测试使用固定 mock。 | F12: staging 与 production 不共用数据库、密钥和预算。 | G12: 05部署§1 | H12: P0 | I12: 是 | J12: 进行中 | K12: =IF(J12="不适用","",IF(J12="已完成",1,IF(J12="待审核",0.9,IF(J12="进行中",0.5,IF(J12="已阻塞",0.25,0))))) -> 0.5 | M12: 第1天 | N12: Codex+我 | O12: =总览!$C$5+0 -> 46215 | Q12: local 与 Railway test 已核验；staging/production 与密钥隔离尚未验证。 | R12: 完成 Vercel/生产 API 域名、生产数据库与 Creem live 环境分层。 | S12: Railway test /api/health、/api/health/ready 均为 200。
A13: DEV-009 | B13: 登录与账号 | C13: Supabase | D13: 创建 Supabase 项目 | E13: 启用 PostgreSQL 与 Auth，选择与目标用户接近的区域，记录项目URL和密钥。 | F13: 开发环境可连接；anon key 仅前端使用，service role 仅服务端使用。 | G13: 用户新增要求；08数据库§4-5 | H13: P0 | I13: 是 | J13: 已完成 | K13: =IF(J13="不适用","",IF(J13="已完成",1,IF(J13="待审核",0.9,IF(J13="进行中",0.5,IF(J13="已阻塞",0.25,0))))) -> 1 | L13: 环境分层 | M13: 第1天 | N13: 我 | O13: =总览!$C$5+0 -> 46215 | Q13: 当前实现与测试环境已存在；关键 API 需要身份验证。 | R13: 保留生产环境的人工验证。 | S13: prisma/schema.prisma；apps/api/src/auth；apps/api/src/api-transport.ts
A14: DEV-010 | B14: 登录与账号 | C14: 数据模型 | D14: 建立 profiles 与用户关联 | E14: 新增 profiles/user_id；StoryRun.userId 与登录用户关联。 | F14: 用户只能读取自己的 StoryRun；数据库存在索引和外键策略。 | G14: 01基线§4.1；08数据库§6 | H14: P0 | I14: 是 | J14: 进行中 | K14: =IF(J14="不适用","",IF(J14="已完成",1,IF(J14="待审核",0.9,IF(J14="进行中",0.5,IF(J14="已阻塞",0.25,0))))) -> 0.5 | L14: Supabase项目 | M14: 第2天 | N14: Codex | O14: =总览!$C$5+1 -> 46216 | Q14: 用户、会话与房间恢复代码已存在，但原表的 Supabase profiles/自动刷新/历史列表口径尚未完整逐项验收。 | R14: 按现行账户模型补充真实浏览器验收。 | S14: apps/api/src/auth；apps/api/src/rooms.service.ts；apps/web/public/platform.js
A15: DEV-011 | B15: 登录与账号 | C15: 登录页 | D15: 实现英文登录/注册页面 | E15: 支持邮箱验证码或 Magic Link；提供错误、发送中、已发送状态。 | F15: 新用户可完成登录，错误邮箱和频率限制有明确提示。 | G15: 用户新增要求 | H15: P0 | I15: 是 | J15: 已完成 | K15: =IF(J15="不适用","",IF(J15="已完成",1,IF(J15="待审核",0.9,IF(J15="进行中",0.5,IF(J15="已阻塞",0.25,0))))) -> 1 | L15: Supabase项目 | M15: 第2天 | N15: Codex | O15: =总览!$C$5+1 -> 46216 | Q15: 当前实现与测试环境已存在；关键 API 需要身份验证。 | R15: 保留生产环境的人工验证。 | S15: prisma/schema.prisma；apps/api/src/auth；apps/api/src/api-transport.ts
A16: DEV-012 | B16: 登录与账号 | C16: 会话 | D16: 实现会话持久化与自动刷新 | E16: 页面刷新、关闭重开后恢复登录；token 过期自动刷新。 | F16: 刷新后不丢失登录；失效会话跳转登录并保留返回地址。 | G16: 用户新增要求 | H16: P0 | I16: 是 | J16: 进行中 | K16: =IF(J16="不适用","",IF(J16="已完成",1,IF(J16="待审核",0.9,IF(J16="进行中",0.5,IF(J16="已阻塞",0.25,0))))) -> 0.5 | L16: 登录页 | M16: 第2天 | N16: Codex | O16: =总览!$C$5+1 -> 46216 | Q16: 用户、会话与房间恢复代码已存在，但原表的 Supabase profiles/自动刷新/历史列表口径尚未完整逐项验收。 | R16: 按现行账户模型补充真实浏览器验收。 | S16: apps/api/src/auth；apps/api/src/rooms.service.ts；apps/web/public/platform.js
A17: DEV-013 | B17: 登录与账号 | C17: 路由保护 | D17: 保护创建局、我的游戏与支付页面 | E17: 未登录用户访问受保护路由时跳转登录；公开首页和法律页面不受影响。 | F17: 受保护 API 同时验证用户身份，不能只依赖前端。 | G17: 用户新增要求；08数据库§16 | H17: P0 | I17: 是 | J17: 已完成 | K17: =IF(J17="不适用","",IF(J17="已完成",1,IF(J17="待审核",0.9,IF(J17="进行中",0.5,IF(J17="已阻塞",0.25,0))))) -> 1 | L17: 会话 | M17: 第2天 | N17: Codex | O17: =总览!$C$5+1 -> 46216 | Q17: 当前实现与测试环境已存在；关键 API 需要身份验证。 | R17: 保留生产环境的人工验证。 | S17: prisma/schema.prisma；apps/api/src/auth；apps/api/src/api-transport.ts
A18: DEV-014 | B18: 登录与账号 | C18: 退出 | D18: 实现退出登录 | E18: 清理本地会话和非权威草稿，返回首页。 | F18: 退出后无法继续调用用户私有 API；再次登录可恢复历史局。 | G18: 用户新增要求 | H18: P0 | I18: 否 | J18: 未开始 | K18: =IF(J18="不适用","",IF(J18="已完成",1,IF(J18="待审核",0.9,IF(J18="进行中",0.5,IF(J18="已阻塞",0.25,0))))) -> 0 | L18: 会话 | M18: 第2天 | N18: Codex | O18: =总览!$C$5+1 -> 46216
A19: DEV-015 | B19: 登录与账号 | C19: 我的游戏 | D19: 实现最近故事局列表 | E19: 展示进行中、已完成、创建时间、当前天数和继续按钮。 | F19: 登录用户可继续自己的局；无法看到其他用户局。 | G19: 用户新增要求；08数据库§6 | H19: P0 | I19: 是 | J19: 进行中 | K19: =IF(J19="不适用","",IF(J19="已完成",1,IF(J19="待审核",0.9,IF(J19="进行中",0.5,IF(J19="已阻塞",0.25,0))))) -> 0.5 | L19: profiles与StoryRun | M19: 第3天 | N19: Codex | O19: =总览!$C$5+2 -> 46217 | Q19: 用户、会话与房间恢复代码已存在，但原表的 Supabase profiles/自动刷新/历史列表口径尚未完整逐项验收。 | R19: 按现行账户模型补充真实浏览器验收。 | S19: apps/api/src/auth；apps/api/src/rooms.service.ts；apps/web/public/platform.js
A20: DEV-016 | B20: 登录与账号 | C20: 账户页 | D20: 实现基础账户与客服入口 | E20: 显示邮箱、Credits/权益、退出、删除账户申请、客服邮箱。 | F20: 用户能看到购买权益和联系支持；敏感字段不暴露。 | G20: Creem审核要求；隐私合规 | H20: P1 | I20: 否 | J20: 未开始 | K20: =IF(J20="不适用","",IF(J20="已完成",1,IF(J20="待审核",0.9,IF(J20="进行中",0.5,IF(J20="已阻塞",0.25,0))))) -> 0 | L20: 登录会话/支付权益 | M20: 第5天 | N20: Codex | O20: =总览!$C$5+4 -> 46219
A21: DEV-017 | B21: 登录与账号 | C21: 数据删除 | D21: 实现账户数据删除/申请流程 | E21: 提供删除请求入口，按隐私政策删除或匿名化用户数据。 | F21: 删除流程可追踪；支付与安全日志按合法保留规则处理。 | G21: Privacy Policy；05部署§9-10 | H21: P1 | I21: 否 | J21: 未开始 | K21: =IF(J21="不适用","",IF(J21="已完成",1,IF(J21="待审核",0.9,IF(J21="进行中",0.5,IF(J21="已阻塞",0.25,0))))) -> 0 | L21: 账户页 | M21: 第6天 | N21: Codex+我 | O21: =总览!$C$5+5 -> 46220
A22: DEV-018 | B22: 登录与账号 | C22: 滥用防护 | D22: 登录频率限制与机器人防护 | E22: 对验证码发送、登录尝试、创建局等入口限流。 | F22: 异常频率返回429，不泄露账号是否存在。 | G22: 05部署§10 | H22: P1 | I22: 否 | J22: 已完成 | K22: =IF(J22="不适用","",IF(J22="已完成",1,IF(J22="待审核",0.9,IF(J22="进行中",0.5,IF(J22="已阻塞",0.25,0))))) -> 1 | L22: 登录页 | M22: 第6天 | N22: Codex | O22: =总览!$C$5+5 -> 46220 | Q22: 当前实现与测试环境已存在；关键 API 需要身份验证。 | R22: 保留生产环境的人工验证。 | S22: prisma/schema.prisma；apps/api/src/auth；apps/api/src/api-transport.ts
A23: DEV-019 | B23: 入口与房间 | C23: 首页 | D23: 英文首页部署与正式域名 | E23: 保持已上线首页可访问，首屏说明产品、玩法、价格和Beta状态。 | F23: 正式域名HTTPS稳定；所有CTA无死链。 | G23: 现有进度表；Creem审核 | H23: P0 | I23: 是 | J23: 已完成 | K23: =IF(J23="不适用","",IF(J23="已完成",1,IF(J23="待审核",0.9,IF(J23="进行中",0.5,IF(J23="已阻塞",0.25,0))))) -> 1 | M23: 第1天 | N23: 我 | O23: =总览!$C$5+0 -> 46215
A24: DEV-020 | B24: 入口与房间 | C24: 故事大厅 | D24: 实现故事局大厅 | E24: 调用 GET /api/v4/stories，展示《桑田诏》卡片、7天、历史权谋和可玩状态。 | F24: 首页/大厅能进入故事详情或角色选择，加载失败有重试。 | G24: 01基线§3；02状态机§9.1 | H24: P0 | I24: 是 | J24: 已完成 | K24: =IF(J24="不适用","",IF(J24="已完成",1,IF(J24="待审核",0.9,IF(J24="进行中",0.5,IF(J24="已阻塞",0.25,0))))) -> 1 | L24: stories API | M24: 第2天 | N24: Codex | O24: =总览!$C$5+1 -> 46216 | Q24: 目录、角色、创建、读取与持久化恢复均有当前实现和自动化验证。 | R24: 在 Vercel 正式域名上补做用户可见流程验收。 | S24: Railway test GET /api/v4/stories=200；apps/api 的 HTTP 全流程与重启持久化断言通过。
A25: DEV-021 | B25: 入口与房间 | C25: 故事详情 | D25: 实现故事详情与规则说明 | E25: 展示钩子、时长、角色、单人Beta说明、开始按钮。 | F25: 用户在30秒内理解目标、7天制和AI决策机制。 | G25: 07 PRD§4-5；09玩法§1-4 | H25: P1 | I25: 否 | J25: 已完成 | K25: =IF(J25="不适用","",IF(J25="已完成",1,IF(J25="待审核",0.9,IF(J25="进行中",0.5,IF(J25="已阻塞",0.25,0))))) -> 1 | L25: 故事大厅 | M25: 第2天 | N25: Codex | O25: =总览!$C$5+1 -> 46216 | Q25: 目录、角色、创建、读取与持久化恢复均有当前实现和自动化验证。 | R25: 在 Vercel 正式域名上补做用户可见流程验收。 | S25: Railway test GET /api/v4/stories=200；apps/api 的 HTTP 全流程与重启持久化断言通过。
A26: DEV-022 | B26: 入口与房间 | C26: 角色选择 | D26: 实现角色选择页 | E26: GET roles；MVP 仅浙江总督可选，其他角色显示AI控制。 | F26: 只能以 zhejiang_governor 正式创建StoryRun。 | G26: 01基线§2；02状态机§9.3-9.4 | H26: P0 | I26: 是 | J26: 已完成 | K26: =IF(J26="不适用","",IF(J26="已完成",1,IF(J26="待审核",0.9,IF(J26="进行中",0.5,IF(J26="已阻塞",0.25,0))))) -> 1 | L26: stories/roles API | M26: 第2天 | N26: Codex | O26: =总览!$C$5+1 -> 46216 | Q26: 目录、角色、创建、读取与持久化恢复均有当前实现和自动化验证。 | R26: 在 Vercel 正式域名上补做用户可见流程验收。 | S26: Railway test GET /api/v4/stories=200；apps/api 的 HTTP 全流程与重启持久化断言通过。
A27: DEV-023 | B27: 入口与房间 | C27: 开启房间 | D27: 创建故事局/开启房间 | E27: 点击开始调用 POST /api/v4/story-runs，使用幂等键，成功后进入 /game?runId=...。 | F27: 创建一次只产生一个StoryRun；初始day=1、version=1、awaiting_decision。 | G27: 02状态机§9.4；用户新增要求 | H27: P0 | I27: 是 | J27: 已完成 | K27: =IF(J27="不适用","",IF(J27="已完成",1,IF(J27="待审核",0.9,IF(J27="进行中",0.5,IF(J27="已阻塞",0.25,0))))) -> 1 | L27: 登录/角色选择/数据库 | M27: 第2天 | N27: Codex | O27: =总览!$C$5+1 -> 46216 | Q27: 目录、角色、创建、读取与持久化恢复均有当前实现和自动化验证。 | R27: 在 Vercel 正式域名上补做用户可见流程验收。 | S27: Railway test GET /api/v4/stories=200；apps/api 的 HTTP 全流程与重启持久化断言通过。
A28: DEV-024 | B28: 入口与房间 | C28: 进入房间 | D28: 输入 runId 或继续上次故事局 | E28: 提供“继续游戏/输入房间ID”入口，GET run 后进入唯一游戏页。 | F28: 合法runId恢复原状态；无效runId明确提示，不静默创建新局。 | G28: 02状态机§7、9.5；用户新增要求 | H28: P0 | I28: 是 | J28: 已完成 | K28: =IF(J28="不适用","",IF(J28="已完成",1,IF(J28="待审核",0.9,IF(J28="进行中",0.5,IF(J28="已阻塞",0.25,0))))) -> 1 | L28: GET StoryRun | M28: 第2天 | N28: Codex | O28: =总览!$C$5+1 -> 46216 | Q28: 目录、角色、创建、读取与持久化恢复均有当前实现和自动化验证。 | R28: 在 Vercel 正式域名上补做用户可见流程验收。 | S28: Railway test GET /api/v4/stories=200；apps/api 的 HTTP 全流程与重启持久化断言通过。
A29: DEV-025 | B29: 入口与房间 | C29: 房间恢复 | D29: 刷新与跨设备恢复 | E29: 浏览器只保存runId和草稿；权威状态从服务端恢复。 | F29: awaiting_decision/resolving/day_advance/finalization/finished 均恢复正确。 | G29: 01基线§4；02状态机§7 | H29: P0 | I29: 是 | J29: 已完成 | K29: =IF(J29="不适用","",IF(J29="已完成",1,IF(J29="待审核",0.9,IF(J29="进行中",0.5,IF(J29="已阻塞",0.25,0))))) -> 1 | L29: 进入房间/状态机 | M29: 第3天 | N29: Codex | O29: =总览!$C$5+2 -> 46217 | Q29: 目录、角色、创建、读取与持久化恢复均有当前实现和自动化验证。 | R29: 在 Vercel 正式域名上补做用户可见流程验收。 | S29: Railway test GET /api/v4/stories=200；apps/api 的 HTTP 全流程与重启持久化断言通过。
A30: DEV-026 | B30: 入口与房间 | C30: 继续/重开 | D30: 完成局后重开新局 | E30: 结局页提供Replay，创建新runId，旧局保持只读。 | F30: 重开不覆盖旧局；用户可在我的游戏查看两局。 | G30: 04验收F-012；02状态机§2 | H30: P1 | I30: 否 | J30: 未开始 | K30: =IF(J30="不适用","",IF(J30="已完成",1,IF(J30="待审核",0.9,IF(J30="进行中",0.5,IF(J30="已阻塞",0.25,0))))) -> 0 | L30: 最终裁决 | M30: 第5天 | N30: Codex | O30: =总览!$C$5+4 -> 46219
A31: DEV-027 | B31: 入口与房间 | C31: 多人边界 | D31: 明确真人加入房间不进入当前MVP | E31: UI文案避免让用户误以为当前支持多人实时；保留未来入口但禁用。 | F31: 正式Beta不出现无法使用的“邀请真人加入”按钮。 | G31: 01基线§2；07 PRD§10 | H31: P0 | I31: 是 | J31: 不适用 | K31: =IF(J31="不适用","",IF(J31="已完成",1,IF(J31="待审核",0.9,IF(J31="进行中",0.5,IF(J31="已阻塞",0.25,0))))) | L31: 范围锁定 | M31: 第2天 | N31: 我+Codex | O31: =总览!$C$5+1 -> 46216 | Q31: 原表限定单人MVP/禁止真人多人；现行代码已演进为房间与多用户实现，原验收口径不再适用。 | R31: 后续以 v1.4 房间/多用户范围重建对应任务与验收口径。 | S31: apps/api/src/rooms.controller.ts；docs/auto-execute/many-worlds-v14-p0-closeout-final-acceptance-gate.md
A32: DEV-028 | B32: 数据库与运行态 | C32: 迁移 | D32: 建立 StoryRun 表 | E32: 保存userId、templateKey、mode、status、day、selectedRoleKey、stateJson、version、时间字段。 | F32: 迁移可重复执行；关键字段和索引符合文档。 | G32: 08数据库§6 | H32: P0 | I32: 是 | J32: 已完成 | K32: =IF(J32="不适用","",IF(J32="已完成",1,IF(J32="待审核",0.9,IF(J32="进行中",0.5,IF(J32="已阻塞",0.25,0))))) -> 1 | L32: Supabase项目 | M32: 第2天 | N32: Codex | O32: =总览!$C$5+1 -> 46216 | Q32: Prisma 持久化、事件、AI任务、版本与幂等控制均在当前代码和测试内。 | R32: 生产数据与权限策略继续按发布环境复核。 | S32: prisma/schema.prisma；apps/api/src/prisma-mvp-storage.ts；apps/api/src/story.service.spec.ts
A33: DEV-029 | B33: 数据库与运行态 | C33: 迁移 | D33: 建立 StoryEvent 表 | E33: 追加式保存故事、prompt、decision、result、change、maneuver、critical、day_end、final等。 | F33: 事件按run/day/time可查询；事件不可被普通业务覆盖修改。 | G33: 08数据库§7 | H33: P0 | I33: 是 | J33: 已完成 | K33: =IF(J33="不适用","",IF(J33="已完成",1,IF(J33="待审核",0.9,IF(J33="进行中",0.5,IF(J33="已阻塞",0.25,0))))) -> 1 | L33: StoryRun表 | M33: 第2天 | N33: Codex | O33: =总览!$C$5+1 -> 46216 | Q33: Prisma 持久化、事件、AI任务、版本与幂等控制均在当前代码和测试内。 | R33: 生产数据与权限策略继续按发布环境复核。 | S33: prisma/schema.prisma；apps/api/src/prisma-mvp-storage.ts；apps/api/src/story.service.spec.ts
A34: DEV-030 | B34: 数据库与运行态 | C34: AI账本 | D34: 建立 AiTask 表 | E34: 真实模型接入时记录任务状态、输入摘要、输出、校验错误、重试、token、成本、耗时。 | F34: 每次主要AI调用可追踪；普通日志不保存敏感全文。 | G34: 08数据库§9；05部署§7 | H34: P0 | I34: 是 | J34: 已完成 | K34: =IF(J34="不适用","",IF(J34="已完成",1,IF(J34="待审核",0.9,IF(J34="进行中",0.5,IF(J34="已阻塞",0.25,0))))) -> 1 | L34: StoryRun/StoryEvent | M34: 第3天 | N34: Codex | O34: =总览!$C$5+2 -> 46217 | Q34: Prisma 持久化、事件、AI任务、版本与幂等控制均在当前代码和测试内。 | R34: 生产数据与权限策略继续按发布环境复核。 | S34: prisma/schema.prisma；apps/api/src/prisma-mvp-storage.ts；apps/api/src/story.service.spec.ts
A35: DEV-031 | B35: 数据库与运行态 | C35: 初始化 | D35: StoryRun 初始状态生成 | E35: 从剧本配置生成世界变量、角色变量、关系、谋划次数、activePrompt和开场事件。 | F35: 创建事务完成后直接进入awaiting_decision；失败不留下半成品run。 | G35: 02状态机§2.1；08数据库§12.1 | H35: P0 | I35: 是 | J35: 已完成 | K35: =IF(J35="不适用","",IF(J35="已完成",1,IF(J35="待审核",0.9,IF(J35="进行中",0.5,IF(J35="已阻塞",0.25,0))))) -> 1 | L35: 配置校验/数据库 | M35: 第2天 | N35: Codex | O35: =总览!$C$5+1 -> 46216 | Q35: Prisma 持久化、事件、AI任务、版本与幂等控制均在当前代码和测试内。 | R35: 生产数据与权限策略继续按发布环境复核。 | S35: prisma/schema.prisma；apps/api/src/prisma-mvp-storage.ts；apps/api/src/story.service.spec.ts
A36: DEV-032 | B36: 数据库与运行态 | C36: 公共投影 | D36: StoryEvent → NarrativeEntry 公共投影 | E36: 过滤hidden事件，将story/result/day_end投影为story，将可见patch投影为change_summary。 | F36: 公共响应不含internalGain/internalRisk/statePatch预测/privateReasoning。 | G36: 08数据库§8；02状态机§8-9.6 | H36: P0 | I36: 是 | J36: 已完成 | K36: =IF(J36="不适用","",IF(J36="已完成",1,IF(J36="待审核",0.9,IF(J36="进行中",0.5,IF(J36="已阻塞",0.25,0))))) -> 1 | L36: StoryEvent表/共享类型 | M36: 第3天 | N36: Codex | O36: =总览!$C$5+2 -> 46217 | Q36: Prisma 持久化、事件、AI任务、版本与幂等控制均在当前代码和测试内。 | R36: 生产数据与权限策略继续按发布环境复核。 | S36: prisma/schema.prisma；apps/api/src/prisma-mvp-storage.ts；apps/api/src/story.service.spec.ts
A37: DEV-033 | B37: 数据库与运行态 | C37: 乐观锁 | D37: 实现 version 并发控制 | E37: 每次权威写入校验version并+1；旧版本返回VERSION_CONFLICT。 | F37: 双标签页并发时只有一个请求成功，状态无覆盖。 | G37: 02状态机§5.1 | H37: P0 | I37: 是 | J37: 已完成 | K37: =IF(J37="不适用","",IF(J37="已完成",1,IF(J37="待审核",0.9,IF(J37="进行中",0.5,IF(J37="已阻塞",0.25,0))))) -> 1 | L37: StoryRun表 | M37: 第3天 | N37: Codex | O37: =总览!$C$5+2 -> 46217 | Q37: Prisma 持久化、事件、AI任务、版本与幂等控制均在当前代码和测试内。 | R37: 生产数据与权限策略继续按发布环境复核。 | S37: prisma/schema.prisma；apps/api/src/prisma-mvp-storage.ts；apps/api/src/story.service.spec.ts
A38: DEV-034 | B38: 数据库与运行态 | C38: 幂等 | D38: 实现 Idempotency-Key 账本 | E38: runId+endpoint+key唯一；相同请求返回同一结果，不同请求体复用key被拒绝。 | F38: 重复点击/网络重试不会重复扣次数、重复写事件或重复支付权益。 | G38: 02状态机§5.2 | H38: P0 | I38: 是 | J38: 已完成 | K38: =IF(J38="不适用","",IF(J38="已完成",1,IF(J38="待审核",0.9,IF(J38="进行中",0.5,IF(J38="已阻塞",0.25,0))))) -> 1 | L38: 数据库事务 | M38: 第3天 | N38: Codex | O38: =总览!$C$5+2 -> 46217 | Q38: Prisma 持久化、事件、AI任务、版本与幂等控制均在当前代码和测试内。 | R38: 生产数据与权限策略继续按发布环境复核。 | S38: prisma/schema.prisma；apps/api/src/prisma-mvp-storage.ts；apps/api/src/story.service.spec.ts
A39: DEV-035 | B39: 数据库与运行态 | C39: 事务 | D39: 决策与谋划原子事务 | E39: 状态更新、事件追加、计数、筹码和version必须全成或全败。 | F39: 注入任一步骤失败后状态与事件均不出现半落账。 | G39: 08数据库§15 | H39: P0 | I39: 是 | J39: 已完成 | K39: =IF(J39="不适用","",IF(J39="已完成",1,IF(J39="待审核",0.9,IF(J39="进行中",0.5,IF(J39="已阻塞",0.25,0))))) -> 1 | L39: 乐观锁/幂等 | M39: 第3天 | N39: Codex | O39: =总览!$C$5+2 -> 46217 | Q39: Prisma 持久化、事件、AI任务、版本与幂等控制均在当前代码和测试内。 | R39: 生产数据与权限策略继续按发布环境复核。 | S39: prisma/schema.prisma；apps/api/src/prisma-mvp-storage.ts；apps/api/src/story.service.spec.ts
A40: DEV-036 | B40: 数据库与运行态 | C40: 权限 | D40: 用户级数据隔离 | E40: API按userId校验StoryRun所有权；service role仅服务端。 | F40: 修改runId不能读取或修改他人的游戏数据。 | G40: Supabase RLS；05部署§10 | H40: P0 | I40: 是 | J40: 已完成 | K40: =IF(J40="不适用","",IF(J40="已完成",1,IF(J40="待审核",0.9,IF(J40="进行中",0.5,IF(J40="已阻塞",0.25,0))))) -> 1 | L40: 登录/StoryRun | M40: 第4天 | N40: Codex | O40: =总览!$C$5+3 -> 46218 | Q40: Prisma 持久化、事件、AI任务、版本与幂等控制均在当前代码和测试内。 | R40: 生产数据与权限策略继续按发布环境复核。 | S40: prisma/schema.prisma；apps/api/src/prisma-mvp-storage.ts；apps/api/src/story.service.spec.ts
A41: DEV-037 | B41: 数据库与运行态 | C41: 备份恢复 | D41: 数据库备份与恢复策略 | E41: staging/prod独立；配置每日备份，MVP恢复目标RPO≤15分钟、RTO≤2小时。 | F41: 至少完成一次从备份恢复到测试项目的演练并记录结果。 | G41: 05部署§12-13 | H41: P1 | I41: 是 | J41: 进行中 | K41: =IF(J41="不适用","",IF(J41="已完成",1,IF(J41="待审核",0.9,IF(J41="进行中",0.5,IF(J41="已阻塞",0.25,0))))) -> 0.5 | L41: 生产数据库 | M41: 第6天 | N41: 我+Codex | O41: =总览!$C$5+5 -> 46220 | Q41: 本地备份/恢复脚本与历史证据存在；当前 Railway/Supabase 生产备份策略未完成验证。 | R41: 完成生产恢复演练与备份保留策略确认。 | S41: scripts/ops；docs/auto-execute/results/db-restore-smoke-*.json
...

Sheet 测试进度
A1: AI多人剧情推演｜MVP测试进度
A3: 已将自动化验收矩阵完整拆入本表，并补充登录、创建/进入房间、Supabase权限、Creem支付和部署冒烟测试。P0测试未全部通过前，不建议公开Limited Beta。
A4: 测试ID | B4: 测试层级 | C4: 模块 | D4: 场景/输入 | E4: 前置条件 | F4: 操作/步骤 | G4: 预期/断言 | H4: 优先级 | I4: 上线阻断 | J4: 状态 | K4: 自动化 | L4: 建议工具 | M4: 计划阶段 | N4: 负责人 | O4: 计划日期 | P4: 实际日期 | Q4: 缺陷ID | R4: 证据/备注
A5: F-001 | B5: Service/HTTP | C5: 功能测试 | D5: 创建新局 | E5: 无 | F5: POST create | G5: 201；第 1 天；`awaiting_decision`；version=1 | H5: P0 | I5: 是 | J5: 未执行 | K5: 自动 | L5: Vitest/Nest/fetch | M5: 第5天 | N5: Codex | O5: =总览!$C$5+4 -> 46219
A6: F-002 | B6: Service/HTTP | C6: 功能测试 | D6: 恢复新局 | E6: 已有 runId | F6: GET run | G6: 返回相同状态与 activePrompt | H6: P0 | I6: 是 | J6: 未执行 | K6: 自动 | L6: Vitest/Nest/fetch | M6: 第5天 | N6: Codex | O6: =总览!$C$5+4 -> 46219
A7: F-003 | B7: Service/HTTP | C7: 功能测试 | D7: 第一次预设决策 | E7: awaiting_decision | F7: 选 A | G7: 写入 1 次 decision；version+1；生成结果消息 | H7: P0 | I7: 是 | J7: 未执行 | K7: 自动 | L7: Vitest/Nest/fetch | M7: 第5天 | N7: Codex | O7: =总览!$C$5+4 -> 46219
A8: F-004 | B8: Service/HTTP | C8: 功能测试 | D8: 第二次决策 | E8: 当日已完成 1 次 | F8: 再选 | G8: 当日完成 2 次；生成 day_end；进入 awaiting_day_advance | H8: P0 | I8: 是 | J8: 未执行 | K8: 自动 | L8: Vitest/Nest/fetch | M8: 第5天 | N8: Codex | O8: =总览!$C$5+4 -> 46219
A9: F-005 | B9: Service/HTTP | C9: 功能测试 | D9: 未完成当天推进 | E9: 只完成 1 次 | F9: advance-day | G9: 409 DAY_NOT_COMPLETE | H9: P0 | I9: 是 | J9: 未执行 | K9: 自动 | L9: Vitest/Nest/fetch | M9: 第5天 | N9: Codex | O9: =总览!$C$5+4 -> 46219
A10: F-006 | B10: Service/HTTP | C10: 功能测试 | D10: 正常推进 | E10: awaiting_day_advance | F10: advance-day | G10: 下一天；decision 计数清零；新 activePrompt | H10: P0 | I10: 是 | J10: 未执行 | K10: 自动 | L10: Vitest/Nest/fetch | M10: 第5天 | N10: Codex | O10: =总览!$C$5+4 -> 46219
A11: F-007 | B11: Service/HTTP | C11: 功能测试 | D11: 12 次决策闭环 | E11: 第 1 天 | F11: 连续完成 6 天 | G11: 共 12 次；无丢失、无重复 | H11: P0 | I11: 是 | J11: 未执行 | K11: 自动 | L11: Vitest/Nest/fetch | M11: 第5天 | N11: Codex | O11: =总览!$C$5+4 -> 46219
A12: F-008 | B12: Service/HTTP | C12: 功能测试 | D12: 第 7 天状态 | E12: 第 6 天完成并推进 | F12: GET run | G12: currentDay=7；awaiting_finalization；activePrompt=null | H12: P0 | I12: 是 | J12: 未执行 | K12: 自动 | L12: Vitest/Nest/fetch | M12: 第5天 | N12: Codex | O12: =总览!$C$5+4 -> 46219
A13: F-009 | B13: Service/HTTP | C13: 功能测试 | D13: 提前 finalize | E13: 第 1—6 天 | F13: finalize | G13: 409 FINALIZATION_NOT_READY | H13: P0 | I13: 是 | J13: 未执行 | K13: 自动 | L13: Vitest/Nest/fetch | M13: 第5天 | N13: Codex | O13: =总览!$C$5+4 -> 46219
A14: F-010 | B14: Service/HTTP | C14: 功能测试 | D14: 正常 finalize | E14: 第 7 天 ready | F14: finalize | G14: finished；完整 finalJudgement | H14: P0 | I14: 是 | J14: 未执行 | K14: 自动 | L14: Vitest/Nest/fetch | M14: 第5天 | N14: Codex | O14: =总览!$C$5+4 -> 46219
A15: F-011 | B15: Service/HTTP | C15: 功能测试 | D15: finished 后再决策 | E15: finished | F15: submit decision | G15: 409 INVALID_RUN_STATE | H15: P0 | I15: 是 | J15: 未执行 | K15: 自动 | L15: Vitest/Nest/fetch | M15: 第5天 | N15: Codex | O15: =总览!$C$5+4 -> 46219
A16: F-012 | B16: Service/HTTP | C16: 功能测试 | D16: 重开一局 | E16: 任意旧局 | F16: create 新 run | G16: 新 runId；旧局不被覆盖 | H16: P0 | I16: 是 | J16: 未执行 | K16: 自动 | L16: Vitest/Nest/fetch | M16: 第5天 | N16: Codex | O16: =总览!$C$5+4 -> 46219
... A29: F-025 | B29: Service/HTTP | C29: 功能测试 | D29: 使用筹码 | E29: leverage 可用 | F29: POST leverage maneuver | G29: 写入 `leverage_used`；筹码状态按规则变化 | H29: P0 | I29: 是 | J29: 未执行 | K29: 自动 | L29: Vitest/Nest/fetch | M29: 第5天 | N29: Codex | O29: =总览!$C$5+4 -> 46219
A30: G-001 | B30: Unit/Service | C30: ActionGuard | D30: “不拦急奏，另写密奏” | G30: `ok` | H30: P0 | I30: 是 | J30: 未执行 | K30: 自动 | L30: Vitest | M30: 第5天 | N30: Codex | O30: =总览!$C$5+4 -> 46219
A31: G-002 | B31: Unit/Service | C31: ActionGuard | D31: “派幕僚查驿站登记” | G31: `ok` 或 `soft_warn` | H31: P0 | I31: 是 | J31: 未执行 | K31: 自动 | L31: Vitest | M31: 第5天 | N31: Codex | O31: =总览!$C$5+4 -> 46219
A32: G-003 | B32: Unit/Service | C32: ActionGuard | D32: “命令皇帝立即处死巡抚” | G32: `blocked`：越权且操控他人 | H32: P0 | I32: 是 | J32: 未执行 | K32: 自动 | L32: Vitest | M32: 第5天 | N32: Codex | O32: =总览!$C$5+4 -> 46219
A33: G-004 | B33: Unit/Service | C33: ActionGuard | D33: “我宣布巡抚已经认罪” | G33: `blocked`：直接宣布结果 | H33: P0 | I33: 是 | J33: 未执行 | K33: 自动 | L33: Vitest | M33: 第5天 | N33: Codex | O33: =总览!$C$5+4 -> 46219
A34: G-005 | B34: Unit/Service | C34: ActionGuard | D34: “凭空拿出完整暗账” | G34: `rewrite_needed`：不存在的证据 | H34: P0 | I34: 是 | J34: 未执行 | K34: 自动 | L34: Vitest | M34: 第5天 | N34: Codex | O34: =总览!$C$5+4 -> 46219
A35: G-006 | B35: Unit/Service | C35: ActionGuard | D35: “跳到第 7 天直接裁决” | G35: `blocked`：跳过阶段 | H35: P0 | I35: 是 | J35: 未执行 | K35: 自动 | L35: Vitest | M35: 第5天 | N35: Codex | O35: =总览!$C$5+4 -> 46219
A36: G-007 | B36: Unit/Service | C36: ActionGuard | D36: “调一百万兵围困京师” | G36: `blocked`：资源与时代权限不符 | H36: P0 | I36: 是 | J36: 未执行 | K36: 自动 | L36: Vitest | M36: 第5天 | N36: Codex | O36: =总览!$C$5+4 -> 46219
A37: G-008 | B37: Unit/Service | C37: ActionGuard | D37: 空 customText | G37: `400 CUSTOM_TEXT_REQUIRED` | H37: P0 | I37: 是 | J37: 未执行 | K37: 自动 | L37: Vitest | M37: 第5天 | N37: Codex | O37: =总览!$C$5+4 -> 46219
A38: G-009 | B38: Unit/Service | C38: ActionGuard | D38: 主线决策超过 200 字 | G38: `400 CUSTOM_TEXT_TOO_LONG` 或前端拒绝 | H38: P0 | I38: 是 | J38: 未执行 | K38: 自动 | L38: Vitest | M38: 第5天 | N38: Codex | O38: =总览!$C$5+4 -> 46219
A39: G-010 | B39: Unit/Service | C39: ActionGuard | D39: 合法但高风险交易 | G39: `soft_warn`，允许继续且提示风险 | H39: P0 | I39: 是 | J39: 未执行 | K39: 自动 | L39: Vitest | M39: 第5天 | N39: Codex | O39: =总览!$C$5+4 -> 46219
A40: G-011 | B40: Unit/Service | C40: ActionGuard | D40: 尝试控制县令具体结论 | G40: 规范化为“要求/试图”，不保证结果 | H40: P0 | I40: 是 | J40: 未执行 | K40: 自动 | L40: Vitest | M40: 第5天 | N40: Codex | O40: =总览!$C$5+4 -> 46219
A41: G-012 | B41: Unit/Service | C41: ActionGuard | D41: 重复提交被拒行动 | G41: 不消耗决策、不增加 version | H41: P0 | I41: 是 | J41: 未执行 | K41: 自动 | L41: Vitest | M41: 第5天 | N41: Codex | O41: =总览!$C$5+4 -> 46219
... A163: W-033 | B163: Web/E2E | C163: Web/UI | D163: 公共字段扫描 | G163: HTML/JSON 不包含 internalGain、internalRisk、statePatch 预测等字段 | H163: P0 | I163: 是 | J163: 未执行 | K163: 自动 | L163: Playwright/jsdom | M163: 第5-6天 | N163: Codex | O163: =总览!$C$5+4 -> 46219
A164: AUTH-001 | B164: HTTP/E2E | C164: 登录与账号 | D164: 新用户邮箱登录 | E164: 无账号 | F164: 输入邮箱并完成验证码/Magic Link | G164: 成功创建用户与会话，跳回原目标页面 | H164: P0 | I164: 是 | J164: 未执行 | K164: 半自动 | L164: Playwright/Supabase | M164: 第5天 | N164: Codex | O164: =总览!$C$5+4 -> 46219
A165: AUTH-002 | B165: HTTP/E2E | C165: 登录与账号 | D165: 已注册用户登录 | E165: 已有账号 | F165: 完成登录 | G165: 恢复同一userId和历史故事局 | H165: P0 | I165: 是 | J165: 未执行 | K165: 半自动 | L165: Playwright/Supabase | M165: 第5天 | N165: Codex | O165: =总览!$C$5+4 -> 46219
A166: AUTH-003 | B166: HTTP/E2E | C166: 登录与账号 | D166: 刷新保持会话 | E166: 已登录 | F166: 刷新页面/重开浏览器 | G166: 登录状态仍有效或自动刷新token | H166: P0 | I166: 是 | J166: 未执行 | K166: 半自动 | L166: Playwright/Supabase | M166: 第5天 | N166: Codex | O166: =总览!$C$5+4 -> 46219
A167: AUTH-004 | B167: HTTP/E2E | C167: 登录与账号 | D167: 过期会话 | E167: token过期 | F167: 访问受保护页面 | G167: 跳转登录，登录后返回原页面 | H167: P0 | I167: 是 | J167: 未执行 | K167: 半自动 | L167: Playwright/Supabase | M167: 第5天 | N167: Codex | O167: =总览!$C$5+4 -> 46219
A168: AUTH-005 | B168: HTTP/E2E | C168: 登录与账号 | D168: 退出登录 | E168: 已登录 | F168: 点击退出 | G168: 私有API不可访问，本地敏感会话被清除 | H168: P0 | I168: 是 | J168: 未执行 | K168: 半自动 | L168: Playwright/Supabase | M168: 第5天 | N168: Codex | O168: =总览!$C$5+4 -> 46219
A169: AUTH-006 | B169: HTTP/E2E | C169: 登录与账号 | D169: 未登录创建局 | E169: 未登录 | F169: POST create | G169: 401/跳转登录，不创建StoryRun | H169: P0 | I169: 是 | J169: 未执行 | K169: 半自动 | L169: Playwright/Supabase | M169: 第5天 | N169: Codex | O169: =总览!$C$5+4 -> 46219
A170: AUTH-007 | B170: HTTP/E2E | C170: 登录与账号 | D170: 越权读取他人run | E170: 用户A/B各有run | F170: B请求A的runId | G170: 404/403，不返回任何状态和事件 | H170: P0 | I170: 是 | J170: 未执行 | K170: 半自动 | L170: Playwright/Supabase | M170: 第5天 | N170: Codex | O170: =总览!$C$5+4 -> 46219
A171: AUTH-008 | B171: HTTP/E2E | C171: 登录与账号 | D171: 我的游戏列表隔离 | E171: 多用户多局 | F171: 获取recent runs | G171: 只返回当前用户的局 | H171: P0 | I171: 是 | J171: 未执行 | K171: 半自动 | L171: Playwright/Supabase | M171: 第5天 | N171: Codex | O171: =总览!$C$5+4 -> 46219
A172: AUTH-009 | B172: HTTP/E2E | C172: 登录与账号 | D172: 登录频率限制 | E172: 连续发送验证码 | F172: 快速重复请求 | G172: 返回429且不泄露账号存在性 | H172: P0 | I172: 是 | J172: 未执行 | K172: 半自动 | L172: Playwright/Supabase | M172: 第5天 | N172: Codex | O172: =总览!$C$5+4 -> 46219
A173: AUTH-010 | B173: HTTP/E2E | C173: 登录与账号 | D173: 账户删除申请 | E173: 有历史局/支付记录 | F173: 提交删除请求 | G173: 按策略删除或匿名化并保留必要审计 | H173: P1 | I173: 否 | J173: 未执行 | K173: 半自动 | L173: Playwright/Supabase | M173: 第5天 | N173: Codex | O173: =总览!$C$5+4 -> 46219
A174: ROOM-001 | B174: E2E | C174: 入口与房间 | D174: 从角色页开启房间 | E174: 已登录且选浙江总督 | F174: 点击开始 | G174: 只创建一个StoryRun并跳转/game?runId | H174: P0 | I174: 是 | J174: 未执行 | K174: 自动 | L174: Playwright/HTTP | M174: 第5天 | N174: Codex | O174: =总览!$C$5+4 -> 46219
...

Sheet 模拟对局
A1: AI多人剧情推演｜模拟对局与稳定性记录
A3: 模拟对局用于证明：12次主线决策、0—12次谋划、关键事件、并发、AI失败、刷新恢复、权限和支付闭环都能稳定完成。SIM-025要求连续20局无死路。
A4: 模拟ID | B4: 场景类型 | C4: 路径/故障注入 | D4: 主线决策策略 | E4: 谋划策略 | F4: 关键事件策略 | G4: 预期重点 | H4: 状态 | I4: 是否通过 | J4: 实际结局 | K4: 完成天数 | L4: 主线决策数 | M4: 谋划次数 | N4: AI调用数 | O4: 总Token | P4: 估算成本 | Q4: Fallback数 | R4: 耗时(分钟) | S4: 缺陷/异常 | T4: 证据/日志
A5: SIM-001 | B5: 主路径 | C5: 全A | D5: 每次选择A | E5: 不使用谋划 | F5: 立即处理 | G5: 状态签名A；到第7天；命中结局A；无死路 | H5: 未执行 | I5: 未执行
A6: SIM-002 | B6: 主路径 | C6: 全B | D6: 每次选择B | E6: 不使用谋划 | F6: 立即处理 | G6: 状态签名B；与全A至少一项结局/关键因果不同 | H6: 未执行 | I6: 未执行
A7: SIM-003 | B7: 主路径 | C7: 全C | D7: 每次选择C | E7: 不使用谋划 | F7: 立即处理 | G7: 状态签名C；与A/B存在差异 | H7: 未执行 | I7: 未执行
A8: SIM-004 | B8: 主路径 | C8: 混合路径 | D8: C,B,C,B,B,C,A,B,C,A,B,B | E8: 不使用谋划 | F8: 按配置 | G8: 12次主线完整；命中可解释结局 | H8: 未执行 | I8: 未执行
A9: SIM-005 | B9: 谋划路径 | C9: 零谋划 | D9: 混合主线 | E9: 每天0次 | F9: 立即处理 | G9: 仍可完成全局结局；未用机会不阻塞 | H9: 未执行 | I9: 未执行
A10: SIM-006 | B10: 谋划路径 | C10: 人物交谈 | D10: 混合主线 | E10: 每天1次contact | F10: 立即处理 | G10: 关系轨迹与零谋划不同 | H10: 未执行 | I10: 未执行
A11: SIM-007 | B11: 谋划路径 | C11: 调查 | D11: 混合主线 | E11: 每天1次investigate | F11: 立即处理 | G11: 线索/证据/FateSeed轨迹发生变化 | H11: 未执行 | I11: 未执行
A12: SIM-008 | B12: 谋划路径 | C12: 使用筹码 | D12: 混合主线 | E12: 每天1次leverage | F12: 立即处理 | G12: 筹码状态和责任/叙事定性变化 | H12: 未执行 | I12: 未执行
A13: SIM-009 | B13: 谋划路径 | C13: 满量谋划 | D13: 混合主线 | E13: 每天2次，共12次 | F13: 立即处理 | G13: 不能超过12次；每天重置；主线仍为12次 | H13: 未执行 | I13: 未执行
A14: SIM-010 | B14: 自定义输入 | C14: 全自定义合法行动 | D14: 每次使用合法自定义文本 | E14: 每天1次自拟谋划 | F14: 立即处理 | G14: ActionGuard允许；输出结构化；无越权 | H14: 未执行 | I14: 未执行
A15: SIM-011 | B15: 关键事件 | C15: 全部立即处理 | D15: 混合主线 | E15: 随机 | F15: 全部立即 | G15: critical_response计入主线槽位，总数仍12 | H15: 未执行 | I15: 未执行
A16: SIM-012 | B16: 关键事件 | C16: 延后再处理 | D16: 混合主线 | E16: 随机 | F16: 先延后，后处理 | G16: 刷新可恢复待处理；只落账一次 | H16: 未执行 | I16: 未执行
... A39: SIM-035 | B39: 备份 | C39: 从事件流重建快照 | D39: 完成到第5天 | E39: 随机 | F39: 随机 | G39: StoryRun与StoryEvent一致，activePrompt正确 | H39: 未执行 | I39: 未执行

Sheet 部署方案
A1: AI多人剧情推演｜MVP部署方案与执行清单
A3: 推荐最少改造方案：Vercel部署现有Web；Railway/Render运行现有NestJS API；Supabase提供PostgreSQL与Auth；Creem负责支付；LLM按调用付费。若坚持不使用Railway，需要先将NestJS和AI长任务改造成Vercel Functions/Workflow。价格以官方页面为准，表内于2026-07-13核对。
A5: 一、推荐架构与服务分工
A6: 层级 | B6: 推荐服务 | C6: 负责内容 | D6: 当前建议 | E6: 成本判断 | F6: 备注 | G6: 官方来源
A7: Web前端 | B7: Vercel | C7: 部署现有 apps/web、CDN、HTTPS、自定义域名 | D7: 当前已使用；继续保留 | E7: Hobby $0；Pro $20/月（商业上线按官方条款选择） | F7: 前端静态资源和普通Web请求 | G7: https://vercel.com/pricing
A8: 后端API | B8: Railway（推荐） | C8: 运行现有 NestJS apps/api、长请求、Health Check | D8: 推荐：最少改造现有后端 | E8: Free含少量资源；Hobby最低$5/月并含$5使用额度 | F8: 若改造成Vercel Functions/Workflow可不使用Railway | G8: https://railway.com/pricing
A9: 数据库 | B9: Supabase PostgreSQL | C9: StoryRun、StoryEvent、AiTask、用户与支付权益 | D9: 推荐 | E9: Free可用于开发；Pro $25/月起 | F9: 运行态权威数据 | G9: https://supabase.com/pricing
A10: 登录 | B10: Supabase Auth | C10: 邮箱验证码/Magic Link、会话和用户ID | D10: 推荐 | E10: Free额度足够早期MVP | F10: 前端anon key；服务端service role | G10: https://supabase.com/docs/guides/auth
A11: 文件 | B11: Vercel public / Supabase Storage | C11: 静态品牌资源放Vercel；用户生成资源放Storage | D11: 按需 | E11: 早期通常免费额度够用 | F11: MVP文本为主，暂不大量存视频 | G11: https://supabase.com/docs/guides/storage
A12: AI | B12: OpenAI/DeepSeek等 | C12: ActionGuard、角色反应、剧情表达 | D12: 必需 | E12: 按调用付费 | F12: 规则引擎仍是状态权威 | G12: https://platform.openai.com/docs / 具体模型供应商官方文档
A13: 支付 | B13: Creem | C13: Checkout、税务/MoR、Webhook、退款/争议 | D13: 正式收费必需 | E13: 通常按交易收费 | F13: 先Test Mode，审核通过后Live | G13: https://docs.creem.io/getting-started/quickstart
A14: 域名与邮件 | B14: Cloudflare DNS + Email Routing | C14: 域名解析、HTTPS辅助、support@转发 | D14: 推荐 | E14: 基础功能可免费 | F14: 客服邮箱需真实可收件 | G14: https://developers.cloudflare.com/email-routing/
A15: 监控 | B15: Vercel/Railway Logs + Sentry | C15: 错误、版本、AI失败与告警 | D15: 推荐 | E15: 早期可用免费额度 | F15: 禁止记录密钥和完整私密输入 | G15: https://sentry.io/pricing/
A16: 分析 | B16: 轻量分析工具 | C16: 来源、登录、开局、决策、结局、支付点击 | D16: 建议 | E16: 可先免费 | F16: 不上传完整自定义文本 | G16: 按实际采用的分析工具官方定价页
A18: 二、环境分层
A19: 环境 | B19: 用途 | C19: 数据库 | D19: AI | E19: 支付 | F19: 密钥 | G19: 数据策略
A20: local | B20: 本地开发 | C20: 本地/开发Supabase项目 | D20: mock/rules优先 | E20: Creem Test | F20: 开发密钥 | G20: 可随时重置
A21: test | B21: 自动化测试 | C21: 每次隔离或事务回滚 | D21: 固定mock | E21: 不调用真实支付 | F21: 测试密钥 | G21: CI自动执行
A22: staging | B22: 上线前试玩验收 | C22: 独立Supabase项目/Schema | D22: 真实模型+fallback+较低预算 | E22: Creem Test | F22: 独立密钥 | G22: 至少完成20局连续模拟
A23: production | B23: 正式Limited Beta | C23: 生产Supabase+备份 | D23: 真实模型+限额+告警 | E23: Creem Live或候补 | F23: 生产密钥 | G23: 与staging完全隔离
A25: 三、部署执行任务
A26: 编号 | B26: 模块 | C26: 部署任务 | D26: 完成标准 | E26: 服务/平台 | F26: 优先级 | G26: 上线阻断 | H26: 状态 | I26: 负责人 | J26: 前置依赖 | K26: 计划阶段 | L26: 卡点/下一步
A27: DEP-001 | B27: 架构决策 | C27: 确认MVP部署组合 | D27: 推荐 Vercel Web + Railway NestJS API + Supabase Auth/Postgres + LLM + Creem。 | E27: 全局 | F27: P0 | G27: 是 | H27: 进行中 | I27: 我 | J27: 代码审计 | K27: 第1天 | L27: 确认是否保留现有NestJS部署到Railway
A28: DEP-002 | B28: Supabase | C28: 创建开发项目 | D28: 创建项目、区域、数据库密码、anon/service role密钥并保存。 | E28: Supabase | F28: P0 | G28: 是 | H28: 未开始 | I28: 我 | K28: 第1天
A29: DEP-003 | B29: Supabase | C29: 创建staging/production隔离 | D29: 至少staging与production不共享数据库和密钥。 | E29: Supabase | F29: P0 | G29: 是 | H29: 未开始 | I29: 我 | J29: 开发项目 | K29: 第5天
A30: DEP-004 | B30: Supabase | C30: 执行Prisma迁移 | D30: 创建StoryRun/StoryEvent/AiTask/profiles/payment_events/entitlements。 | E30: Supabase | F30: P0 | G30: 是 | H30: 未开始 | I30: Codex | J30: 数据库模型 | K30: 第5天
A31: DEP-005 | B31: Supabase | C31: 配置RLS与服务端访问 | D31: 用户只能访问自己的run；service role仅API环境。 | E31: Supabase | F31: P0 | G31: 是 | H31: 未开始 | I31: Codex | J31: 登录/表结构 | K31: 第5天
A32: DEP-006 | B32: Supabase | C32: 启用备份与恢复记录 | D32: 生产阶段每日备份，记录恢复步骤和责任人。 | E32: Supabase | F32: P1 | G32: 是 | H32: 未开始 | I32: 我+Codex | J32: production | K32: 第6天
A33: DEP-007 | B33: Vercel | C33: 绑定正式域名 | D33: ourmanyworlds.com HTTPS稳定，www重定向策略明确。 | E33: Vercel/Cloudflare | F33: P0 | G33: 是 | H33: 已完成 | I33: 我 | K33: 第1天
A34: DEP-008 | B34: Vercel | C34: 配置构建命令与输出目录 | D34: apps/web生产构建可重复执行。 | E34: Vercel | F34: P0 | G34: 是 | H34: 待确认 | I34: Codex | J34: 代码审计 | K34: 第5天
A35: DEP-009 | B35: Vercel | C35: 配置前端环境变量 | D35: PUBLIC_API_BASE_URL、Supabase public URL/anon key、分析配置。 | E35: Vercel | F35: P0 | G35: 是 | H35: 未开始 | I35: 我+Codex | J35: API域名/Supabase | K35: 第6天
A36: DEP-010 | B36: Vercel | C36: 配置Preview与Production | D36: PR/分支预览不连接生产数据库和Live支付。 | E36: Vercel | F36: P0 | G36: 是 | H36: 未开始 | I36: Codex | J36: 环境分层 | K36: 第6天
A37: DEP-011 | B37: 后端平台 | C37: 创建Railway API服务 | D37: 从仓库部署apps/api，配置启动命令、端口和自动重启。 | E37: Railway | F37: P0 | G37: 是 | H37: 未开始 | I37: 我+Codex | J37: 架构决策 | K37: 第5天
A38: DEP-012 | B38: 后端平台 | C38: 配置Health Check | D38: /health返回200并检查数据库连接。 | E38: Railway | F38: P0 | G38: 是 | H38: 未开始 | I38: Codex | J38: API实现 | K38: 第5天
A39: DEP-013 | B39: 后端平台 | C39: 配置API域名 | D39: 使用api.ourmanyworlds.com或Vercel反向代理，启用HTTPS。 | E39: Railway/Cloudflare | F39: P0 | G39: 是 | H39: 未开始 | I39: 我 | J39: Railway服务 | K39: 第6天
A40: DEP-014 | B40: 后端平台 | C40: 配置资源与超时 | D40: 低配CPU/内存起步；AI请求25秒超时+1次重试+fallback。 | E40: Railway/API | F40: P0 | G40: 是 | H40: 未开始 | I40: Codex | J40: AI实现 | K40: 第6天
A41: DEP-015 | B41: 后端平台 | C41: 部署staging API | D41: 使用staging数据库、Creem Test、测试AI预算。 | E41: Railway | F41: P0 | G41: 是 | H41: 未开始 | I41: Codex | J41: staging环境 | K41: 第6天
A42: DEP-016 | B42: 后端平台 | C42: 部署production API | D42: 使用生产数据库、Live/候补支付和正式告警。 | E42: Railway | F42: P0 | G42: 是 | H42: 未开始 | I42: Codex | J42: staging验收 | K42: 第7天
A43: DEP-017 | B43: 域名/CORS | C43: 配置Web到API跨域 | D43: 只允许正式/预览域名；Cookie/Auth头正常。 | E43: API/Cloudflare | F43: P0 | G43: 是 | H43: 未开始 | I43: Codex | J43: API域名 | K43: 第6天
A44: DEP-018 | B44: Creem | C44: 配置Test API Key | D44: 后端能创建测试Checkout，密钥不进入前端。 | E44: Creem/API | F44: P0 | G44: 是 | H44: 进行中 | I44: 我+Codex | K44: 第4天
...

Sheet 研发总览
A1: AI多人剧情推演｜研发、测试与部署总览
A3: 本页按新增细分任务自动汇总。注意：开发拆分后包含登录、数据库、后端、AI、支付、测试与部署，计算完成度可能明显低于原先“约30%”的体感。
A5: 开发任务 | D5: 测试用例 | G5: 模拟对局 | J5: 部署任务
A6: 总数 | B6: 已完成 | C6: 完成率 | D6: 总数 | E6: 已通过 | F6: 通过率 | G6: 总数 | H6: 已通过 | I6: 通过率 | J6: 总数 | K6: 已完成 | L6: 完成率
A7: =COUNTA(开发进度!$D$5:$D$300) -> 141 | B7: =COUNTIF(开发进度!$J$5:$J$300,"已完成") -> 86 | C7: =IFERROR(AVERAGE(开发进度!$K$5:$K$300),0) -> 0.75755396 | D7: =COUNTA(测试进度!$A$5:$A$400) -> 207 | E7: =COUNTIF(测试进度!$J$5:$J$400,"通过") -> 0 | F7: =IFERROR(E7/D7,0) -> 0 | G7: =COUNTA(模拟对局!$A$5:$A$100) -> 35 | H7: =COUNTIF(模拟对局!$H$5:$H$100,"通过") -> 0 | I7: =IFERROR(H7/G7,0) -> 0 | J7: =COUNTA(部署方案!$C$27:$C$60) -> 34 | K7: =COUNTIF(部署方案!$H$27:$H$60,"已完成") -> 1 | L7: =IFERROR(K7/J7,0) -> 0.029411765
A9: 开发模块进度 | H9: 测试模块进度
A10: 模块 | B10: 任务数 | C10: 已完成 | D10: 进行中/待审核 | E10: 已阻塞 | F10: 完成率 | H10: 模块 | I10: 用例数 | J10: 通过 | K10: 失败/阻塞 | L10: 通过率
A11: 工程基线 | B11: =COUNTIF(开发进度!$B$5:$B$300,A11) -> 8 | C11: =COUNTIFS(开发进度!$B$5:$B$300,A11,开发进度!$J$5:$J$300,"已完成") -> 5 | D11: =COUNTIFS(开发进度!$B$5:$B$300,A11,开发进度!$J$5:$J$300,"进行中")+COUNTIFS(开发进度!$B$5:$B$300,A11,开发进度!$J$5:$J$300,"待审核") -> 2 | E11: =COUNTIFS(开发进度!$B$5:$B$300,A11,开发进度!$J$5:$J$300,"已阻塞") -> 0 | F11: =IFERROR(AVERAGEIF(开发进度!$B$5:$B$300,A11,开发进度!$K$5:$K$300),0) -> 0.85714286 | H11: 功能测试 | I11: =COUNTIF(测试进度!$C$5:$C$400,H11) -> 25 | J11: =COUNTIFS(测试进度!$C$5:$C$400,H11,测试进度!$J$5:$J$400,"通过") -> 0 | K11: =COUNTIFS(测试进度!$C$5:$C$400,H11,测试进度!$J$5:$J$400,"失败")+COUNTIFS(测试进度!$C$5:$C$400,H11,测试进度!$J$5:$J$400,"已阻塞") -> 0 | L11: =IFERROR(J11/I11,0) -> 0
A12: 登录与账号 | B12: =COUNTIF(开发进度!$B$5:$B$300,A12) -> 10 | C12: =COUNTIFS(开发进度!$B$5:$B$300,A12,开发进度!$J$5:$J$300,"已完成") -> 4 | D12: =COUNTIFS(开发进度!$B$5:$B$300,A12,开发进度!$J$5:$J$300,"进行中")+COUNTIFS(开发进度!$B$5:$B$300,A12,开发进度!$J$5:$J$300,"待审核") -> 3 | E12: =COUNTIFS(开发进度!$B$5:$B$300,A12,开发进度!$J$5:$J$300,"已阻塞") -> 0 | F12: =IFERROR(AVERAGEIF(开发进度!$B$5:$B$300,A12,开发进度!$K$5:$K$300),0) -> 0.55 | H12: ActionGuard | I12: =COUNTIF(测试进度!$C$5:$C$400,H12) -> 18 | J12: =COUNTIFS(测试进度!$C$5:$C$400,H12,测试进度!$J$5:$J$400,"通过") -> 0 | K12: =COUNTIFS(测试进度!$C$5:$C$400,H12,测试进度!$J$5:$J$400,"失败")+COUNTIFS(测试进度!$C$5:$C$400,H12,测试进度!$J$5:$J$400,"已阻塞") -> 0 | L12: =IFERROR(J12/I12,0) -> 0
A13: 入口与房间 | B13: =COUNTIF(开发进度!$B$5:$B$300,A13) -> 9 | C13: =COUNTIFS(开发进度!$B$5:$B$300,A13,开发进度!$J$5:$J$300,"已完成") -> 7 | D13: =COUNTIFS(开发进度!$B$5:$B$300,A13,开发进度!$J$5:$J$300,"进行中")+COUNTIFS(开发进度!$B$5:$B$300,A13,开发进度!$J$5:$J$300,"待审核") -> 0 | E13: =COUNTIFS(开发进度!$B$5:$B$300,A13,开发进度!$J$5:$J$300,"已阻塞") -> 0 | F13: =IFERROR(AVERAGEIF(开发进度!$B$5:$B$300,A13,开发进度!$K$5:$K$300),0) -> 0.875 | H13: 因果与状态 | I13: =COUNTIF(测试进度!$C$5:$C$400,H13) -> 22 | J13: =COUNTIFS(测试进度!$C$5:$C$400,H13,测试进度!$J$5:$J$400,"通过") -> 0 | K13: =COUNTIFS(测试进度!$C$5:$C$400,H13,测试进度!$J$5:$J$400,"失败")+COUNTIFS(测试进度!$C$5:$C$400,H13,测试进度!$J$5:$J$400,"已阻塞") -> 0 | L13: =IFERROR(J13/I13,0) -> 0
